Workbook

Sheet README
A1: Coliseum of Parliament — Starter Card & Stage Data
A2: Purpose | B2: Source-of-truth data for the rhetoric card battler. Each tab = one data table the engine reads (export each tab to CSV/JSON). Keep IDs stable; rename freely.
A3: Status | B3: STARTER / PLACEHOLDER. Canon fields come from the Lore Databook; every number is a first-pass value for playtesting.
A5: TAB GUIDE
A6: Balance | B6: Global levers: power-score weights, deck shares, XP tiers, bill difficulty, committee size by difficulty, Jiban & Party support thresholds.
A7: Suits | B7: The six canon rhetorical Elements → card suits, with proposed Japanese names.
A8: Affinity | B8: Suit × Stage power multipliers. Drives 'favored suit' per stage and the CardStage view.
A9: Cards | B9: 24 starter cards (4 per suit). Power Score and Power/Cost are formulas for balancing.
A10: CardStage | B10: Read-only view: each card's effective power in each stage (Power Score × Affinity).
A11: Stages | B11: Seven combat stages (incl. ST08 Party Steering Committee) + one non-combat mode (陳情 office hours).
A12: Segments | B12: Audience segments that Jinmyaku modifiers key off.
A13: Modifiers | B13: Modifier effects (M01–M15), each linked to its source booster organization.
A14: Opponents | B14: Nine canon MPs (2018 roster) incl. Walter Peard; deck composition derived from their Elements.
A15: Yoron | B15: 世論 public-opinion topics (drawn from databook policy dimensions).
A16: Bills | B16: Example bills; difficulty modifier is computed from Yoron alignment.
A17: Modules | B17: Module 01 vertical slice: stage sequence with computed opponent start support and XP. Committee size/opposition read from Committee tab.
... A19: Lists | B19: Dropdown sources for data validation.
A21: COLOR KEY
A22: Blue text | B22: Hardcoded input — edit freely.
A23: Black text | B23: Formula — do not overwrite.
A24: Green text | B24: Direct link to another tab.
A25: Yellow fill | B25: Open design decision — needs your call.
A27: SOURCING / CONFIDENCE
A28: Canon [H] | B28: Opponent name, party, committee, Positioning, Element 1/2; 101 seats / 51 majority; Element list. Source: Lore Databook 6.10.25, October_2018_Politicians & Party_and_Coalition sheets.
A29: Proposed [M] | B29: All Japanese mechanic/card names — review for tone; many are real Japanese political terms (根回し, 玉虫色, 記憶にございません, 三バン, 番記者).
A30: Placeholder [L] | B30: All numbers, bill titles, committee size (11), Yoron starting values (50).
A32: OPEN DECISIONS
A33: 1. Jiban floor | B33: RESOLVED: Jiban ≤ 15 triggers Town Hall event; Jiban = 0 freezes all funding. Recall dropped.
A34: 2. Protagonist | B34: Canon MP or new character? Party determines the Caucus opponent (Modules row 3).
A35: 3. Yoron seeding | B35: Seed from databook party scores, or set independently (keeps lore separate from analytics)?
A36: 4. Committee size | B36: RESOLVED: Easy 3–5, Hard 8–10 (Normal 6–7 proposed, Balance!A21). Set per module in Modules col N.
A37: 5. Data hygiene | B37: Databook Positioning value 'Authortarian' is misspelled — fix before engine string-matching.
A38: 6. Steering name | B38: Stage ST08 Japanese name: 党運営委員会 (proposed) vs 総務会.
A39: 7. Party thresholds | B39: RESOLVED: >75 allied buff (M09); <50 debuff (M10); <25 Steering Committee (ST08). Magnitudes are placeholders.
A41: TABS ADDED (REV 3)
A42: Boosters | B42: 10 booster organizations (2 Party / 4 Constituency / 4 National) with linked modifiers and tier-balance check.
A43: Committee | B43: Canon Environment committee members for Module 01 with proposed starting stances.
A44: Assets | B44: Production inventory: ~190 visual assets, audio, text; Status dropdown and progress summary (cols L–P).
A46: MORE OPEN DECISIONS
A47: 8. Turn-limit ending | B47: If neither side reaches threshold at the turn limit: loss, tie, or highest support wins?
...

Sheet Balance
A1: Lever | B1: Value | C1: Note
A2: W_self (own support gain) | B2: 1 | C2: Weight in Power Score
A3: W_opp (opponent support loss) | B3: 1.2 | C3: Swing value > self gain: it moves the relative gap directly
A4: W_guard (block) | B4: 0.6 | C4: Block only matters if opponent attacks
A5: W_draw (per card drawn) | B5: 2 | C5: Card advantage
A6: W_gaffe (失言 penalty per point) | B6: 1.5 | C6: Risk cost of gaffe meter
A8: Starter deck size | B8: 12 | C8: Player and default opponent deck size
A9: Primary suit share | B9: 0.5 | C9: Opponent deck share from Element 1
A10: Secondary suit share | B10: 0.3 | C10: Opponent deck share from Element 2
A11: XP TIER TABLE
A12: Starter | B12: 0 | C12: XP to unlock — tier table
A13: Tier 1 | B13: 60 | C13: XP to unlock
A14: Tier 2 | B14: 120 | C14: XP to unlock
A16: Bill difficulty factor | B16: 0.2 | C16: Opp start support change per point of Yoron misalignment
A17: Yoron neutral point | B17: 50 | C17: Opinion value treated as neutral (0–100 scale)
A19: COMMITTEE SIZE BY DIFFICULTY | B19: Min | C19: Max
A20: Easy | B20: 3 | C20: 5
A21: Normal | B21: 6 | C21: 7
A22: Hard | B22: 8 | C22: 10
A23: Committee: share of members opposed at start | B23: 0.4 | C23: Fallback only when a committee stage has no members listed in the Committee tab
A25: Jiban Town Hall trigger (≤) | B25: 15 | C25: Cameron decision: triggers Town Hall event
A26: Jiban funding freeze (≤) | B26: 0 | C26: Cameron decision: all funding frozen
A27: Party support: allied buff (>) | B27: 75 | C27: Cameron decision → M09
A28: Party support: debuff (<) | B28: 50 | C28: Cameron decision → M10
A29: Party support: Steering Committee (<) | B29: 25 | C29: Cameron decision → ST08

Sheet Suits
A1: Element (canon) | B1: Suit (JP) | C1: Romaji | D1: Gloss | E1: Play pattern | F1: Cards in pool
A2: Earnest | B2: 誠実 | C2: Seijitsu | D2: sincerity | E2: Steady own-support gain; resists and cleans up gaffes | F2: =COUNTIF(Cards!$E$2:$E$200,A2) -> 4
A3: Emotional | B3: 情熱 | C3: Jōnetsu | D3: passion | E3: Burst gains that scale with crowd size; some gaffe risk | F3: =COUNTIF(Cards!$E$2:$E$200,A3) -> 4
A4: Appeal | B4: 求心 | C4: Kyūshin | D4: rallying pull | E4: Segment-targeted gains, setup and card flow (根回し) | F4: =COUNTIF(Cards!$E$2:$E$200,A4) -> 4
A5: Data Driven | B5: 実証 | C5: Jisshō | D5: evidence | E5: Refutation: lowers opponent support; strong in committee | F5: =COUNTIF(Cards!$E$2:$E$200,A5) -> 4
A6: Divisive | B6: 分断 | C6: Bundan | D6: division | E6: Steals support both ways; polarizes; moderate gaffe risk | F6: =COUNTIF(Cards!$E$2:$E$200,A6) -> 4
A7: Duplicitous | B7: 二枚舌 | C7: Nimaijita | D7: two tongues | E7: High power and strong guards, heavy gaffe accrual | F7: =COUNTIF(Cards!$E$2:$E$200,A7) -> 4

Sheet Stages
A1: Stage ID | B1: Stage (EN) | C1: Stage (JP) | D1: Romaji | E1: Mode | F1: Bar unit | G1: Bar max | H1: Win threshold | I1: Win % | J1: Turn limit | K1: 持ち時間 / turn (energy) | L1: Hand size | M1: 失言 gaffe limit | N1: Player start | O1: Opp start | P1: % Press | Q1: % Loyalists | R1: % Constituents | S1: % Donors | T1: % Bureaucrats | U1: Segment check | V1: Favored suit | W1: Win ΔJiban | X1: Win ΔKanban | Y1: Win ΔKaban | Z1: XP reward | AA1: Signature rule | AB1: Win ΔParty support
A2: ST01 | B2: Committee | C2: 委員会 | D2: Iinkai | E2: Combat | F2: Members | G2: varies | H2: majority | I2: =IF(AND(ISNUMBER(G2),ISNUMBER(H2)),IF(G2=0,"",H2/G2),"varies") -> varies | J2: 6 | K2: 3 | L2: 5 | M2: 5 | N2: varies | O2: varies | P2: 0.1 | Q2: 0.4 | R2: 0 | S2: 0 | T2: 0.5 | U2: =SUM(P2:T2) -> 1 | V2: =IF(E2<>"Combat","—",IFERROR(INDEX(Affinity!$A$2:$A$7,MATCH(MAX(INDEX(Affinity!$B$2:$H$7,0,MATCH(A2,Affinity!$B$1:$H$1,0))),INDEX(Affinity!$B$2:$H$7,0,MATCH(A2,Affinity!$B$1:$H$1,0)),0)),"—")) -> Data Driven | W2: 0 | X2: 1 | Y2: 0 | Z2: 20 | AA2: Each member has a Positioning; winning a member locks their vote. | AB2: 0
A3: ST02 | B3: Floor Debate | C3: 本会議 | D3: Honkaigi | E3: Combat | F3: Seats | G3: 101 | H3: 51 | I3: =IF(AND(ISNUMBER(G3),ISNUMBER(H3)),IF(G3=0,"",H3/G3),"varies") -> 0.5049505 | J3: 8 | K3: 3 | L3: 5 | M3: 6 | N3: 40 | O3: 40 | P3: 0.2 | Q3: 0.6 | R3: 0.1 | S3: 0 | T3: 0.1 | U3: =SUM(P3:T3) -> 1 | V3: =IF(E3<>"Combat","—",IFERROR(INDEX(Affinity!$A$2:$A$7,MATCH(MAX(INDEX(Affinity!$B$2:$H$7,0,MATCH(A3,Affinity!$B$1:$H$1,0))),INDEX(Affinity!$B$2:$H$7,0,MATCH(A3,Affinity!$B$1:$H$1,0)),0)),"—")) -> Appeal | W3: 1 | X3: 2 | Y3: 0 | Z3: 40 | AA3: Party blocs vote together; flip a bloc to swing seats. | AB3: 3
A4: ST03 | B4: Party Caucus | C4: 議員総会 | D4: Giin Sōkai | E4: Combat | F4: Support | G4: 100 | H4: 60 | I4: =IF(AND(ISNUMBER(G4),ISNUMBER(H4)),IF(G4=0,"",H4/G4),"varies") -> 0.6 | J4: 6 | K4: 3 | L4: 5 | M4: 5 | N4: 40 | O4: 40 | P4: 0 | Q4: 0.9 | R4: 0 | S4: 0.1 | T4: 0 | U4: =SUM(P4:T4) -> 1 | V4: =IF(E4<>"Combat","—",IFERROR(INDEX(Affinity!$A$2:$A$7,MATCH(MAX(INDEX(Affinity!$B$2:$H$7,0,MATCH(A4,Affinity!$B$1:$H$1,0))),INDEX(Affinity!$B$2:$H$7,0,MATCH(A4,Affinity!$B$1:$H$1,0)),0)),"—")) -> Appeal | W4: 0 | X4: 0 | Y4: 0 | Z4: 25 | AA4: Result feeds 党内支持 Party support (Sanban row 5). | AB4: 10
A5: ST04 | B5: Press Conference | C5: 記者会見 | D5: Kisha Kaiken | E5: Combat | F5: Press tone | G5: 100 | H5: 55 | I5: =IF(AND(ISNUMBER(G5),ISNUMBER(H5)),IF(G5=0,"",H5/G5),"varies") -> 0.55 | J5: 5 | K5: 3 | L5: 5 | M5: 4 | N5: 45 | O5: 45 | P5: 0.9 | Q5: 0 | R5: 0 | S5: 0 | T5: 0.1 | U5: =SUM(P5:T5) -> 1 | V5: =IF(E5<>"Combat","—",IFERROR(INDEX(Affinity!$A$2:$A$7,MATCH(MAX(INDEX(Affinity!$B$2:$H$7,0,MATCH(A5,Affinity!$B$1:$H$1,0))),INDEX(Affinity!$B$2:$H$7,0,MATCH(A5,Affinity!$B$1:$H$1,0)),0)),"—")) -> Earnest | W5: 0 | X5: 3 | Y5: 0 | Z5: 25 | AA5: Questions arrive as enemy intents; gaffe limit is tight. | AB5: 0
A6: ST05 | B6: Town Hall | C6: 住民集会 | D6: Jūmin Shūkai | E6: Combat | F6: Support | G6: 100 | H6: 60 | I6: =IF(AND(ISNUMBER(G6),ISNUMBER(H6)),IF(G6=0,"",H6/G6),"varies") -> 0.6 | J6: 6 | K6: 3 | L6: 5 | M6: 6 | N6: 40 | O6: 40 | P6: 0.1 | Q6: 0.1 | R6: 0.7 | S6: 0.1 | T6: 0 | U6: =SUM(P6:T6) -> 1 | V6: =IF(E6<>"Combat","—",IFERROR(INDEX(Affinity!$A$2:$A$7,MATCH(MAX(INDEX(Affinity!$B$2:$H$7,0,MATCH(A6,Affinity!$B$1:$H$1,0))),INDEX(Affinity!$B$2:$H$7,0,MATCH(A6,Affinity!$B$1:$H$1,0)),0)),"—")) -> Emotional | W6: 4 | X6: 1 | Y6: 0 | Z6: 20 | AA6: Heckler events add random debuffs; win feeds Jiban. | AB6: 0
A7: ST06 | B7: TV Debate / Interview | C7: 討論番組 | D7: Tōron Bangumi | E7: Combat | F7: Support | G7: 100 | H7: 50 | I7: =IF(AND(ISNUMBER(G7),ISNUMBER(H7)),IF(G7=0,"",H7/G7),"varies") -> 0.5 | J7: 6 | K7: 3 | L7: 5 | M7: 5 | N7: 50 | O7: 50 | P7: 0.5 | Q7: 0.2 | R7: 0.3 | S7: 0 | T7: 0 | U7: =SUM(P7:T7) -> 1 | V7: =IF(E7<>"Combat","—",IFERROR(INDEX(Affinity!$A$2:$A$7,MATCH(MAX(INDEX(Affinity!$B$2:$H$7,0,MATCH(A7,Affinity!$B$1:$H$1,0))),INDEX(Affinity!$B$2:$H$7,0,MATCH(A7,Affinity!$B$1:$H$1,0)),0)),"—")) -> Data Driven | W7: 0 | X7: 3 | Y7: 0 | Z7: 25 | AA7: Win = stay at/above threshold every turn (survival). | AB7: 0
A8: ST07 | B8: Office Hours | C8: 陳情 | D8: Chinjō | E8: Non-combat | F8: Time slots | I8: =IF(AND(ISNUMBER(G8),ISNUMBER(H8)),IF(G8=0,"",H8/G8),"varies") -> varies | K8: 5 | P8: 0 | Q8: 0 | R8: 0.6 | S8: 0.3 | T8: 0.1 | U8: =SUM(P8:T8) -> 1 | V8: =IF(E8<>"Combat","—",IFERROR(INDEX(Affinity!$A$2:$A$7,MATCH(MAX(INDEX(Affinity!$B$2:$H$7,0,MATCH(A8,Affinity!$B$1:$H$1,0))),INDEX(Affinity!$B$2:$H$7,0,MATCH(A8,Affinity!$B$1:$H$1,0)),0)),"—")) -> — | Z8: 10 | AA8: Visitors arrive as event cards; spend time slots to respond. Outputs Jiban, Kaban, unlocks.
A9: ST08 | B9: Party Steering Committee | C9: 党運営委員会 | D9: Tō Un'ei Iinkai | E9: Combat | F9: Support | G9: 100 | H9: 60 | I9: =IF(AND(ISNUMBER(G9),ISNUMBER(H9)),IF(G9=0,"",H9/G9),"varies") -> 0.6 | J9: 6 | K9: 3 | L9: 5 | M9: 5 | N9: 20 | O9: 50 | P9: 0 | Q9: 0.8 | R9: 0 | S9: 0 | T9: 0.2 | U9: =SUM(P9:T9) -> 1 | V9: =IF(E9<>"Combat","—",IFERROR(INDEX(Affinity!$A$2:$A$7,MATCH(MAX(INDEX(Affinity!$B$2:$H$7,0,MATCH(A9,Affinity!$B$1:$H$1,0))),INDEX(Affinity!$B$2:$H$7,0,MATCH(A9,Affinity!$B$1:$H$1,0)),0)),"—")) -> Appeal | W9: 0 | X9: -3 | Y9: -20 | Z9: 15 | AA9: Triggered when Party support < 25. Entry cost: one Kōenkai and one Bankisha modifier disabled for the next module. Win restores Party support. | AB9: 30

Sheet Affinity
A1: Element | B1: ST01 | C1: ST02 | D1: ST03 | E1: ST04 | F1: ST05 | G1: ST06 | H1: ST08
A2: Earnest | B2: 1 | C2: 1 | D2: 1.1 | E2: 1.2 | F2: 1.2 | G2: 1.1 | H2: 1.2
A3: Emotional | B3: 0.8 | C3: 1.1 | D3: 1 | E3: 0.9 | F3: 1.3 | G3: 1 | H3: 0.9
A4: Appeal | B4: 1 | C4: 1.2 | D4: 1.25 | E4: 0.9 | F4: 1.1 | G4: 1 | H4: 1.3
A5: Data Driven | B5: 1.3 | C5: 1.1 | D5: 0.9 | E5: 1 | F5: 0.8 | G5: 1.2 | H5: 1
A6: Divisive | B6: 0.8 | C6: 1.2 | D6: 0.8 | E6: 1 | F6: 1.1 | G6: 1.1 | H6: 0.7
A7: Duplicitous | B7: 1.1 | C7: 1 | D7: 1.1 | E7: 0.7 | F7: 0.9 | G7: 0.8 | H7: 1
A9: Stage name → | B9: =IFERROR(INDEX(Stages!$B$2:$B$9,MATCH(B$1,Stages!$A$2:$A$9,0)),"") -> Committee | C9: =IFERROR(INDEX(Stages!$B$2:$B$9,MATCH(C$1,Stages!$A$2:$A$9,0)),"") -> Floor Debate | D9: =IFERROR(INDEX(Stages!$B$2:$B$9,MATCH(D$1,Stages!$A$2:$A$9,0)),"") -> Party Caucus | E9: =IFERROR(INDEX(Stages!$B$2:$B$9,MATCH(E$1,Stages!$A$2:$A$9,0)),"") -> Press Conference | F9: =IFERROR(INDEX(Stages!$B$2:$B$9,MATCH(F$1,Stages!$A$2:$A$9,0)),"") -> Town Hall | G9: =IFERROR(INDEX(Stages!$B$2:$B$9,MATCH(G$1,Stages!$A$2:$A$9,0)),"") -> TV Debate / Interview | H9: =IFERROR(INDEX(Stages!$B$2:$B$9,MATCH(H$1,Stages!$A$2:$A$9,0)),"") -> Party Steering Committee
A10: Column average | B10: =AVERAGE(B2:B7) -> 1 | C10: =AVERAGE(C2:C7) -> 1.1 | D10: =AVERAGE(D2:D7) -> 1.025 | E10: =AVERAGE(E2:E7) -> 0.95 | F10: =AVERAGE(F2:F7) -> 1.0666667 | G10: =AVERAGE(G2:G7) -> 1.0333333 | H10: =AVERAGE(H2:H7) -> 1.0166667

Sheet Cards
A1: Card ID | B1: Name (EN) | C1: Name (JP) | D1: Romaji | E1: Suit (Element) | F1: Suit (JP) | G1: Type | H1: Cost (持ち時間) | I1: Self + | J1: Opp − | K1: Guard | L1: Draw | M1: Gaffe +/− | N1: Target segment | O1: Effect text | P1: Upgrade (+) | Q1: Tier | R1: XP to unlock | S1: Power Score | T1: Power / Cost | U1: Balance flag
A2: C01 | B2: Record of Service | C2: 実績報告 | D2: Jisseki Hōkoku | E2: Earnest | F2: =IFERROR(INDEX(Suits!$B$2:$B$7,MATCH(E2,Suits!$A$2:$A$7,0)),"?") -> 誠実 | G2: Gain | H2: 1 | I2: 3 | J2: 0 | K2: 0 | L2: 0 | M2: 0 | N2: Any | O2: Gain 3 support. | P2: Gain 4. | Q2: Starter | R2: =IFERROR(INDEX(Balance!$B$12:$B$14,MATCH(Q2,Balance!$A$12:$A$14,0)),"") -> 0 | S2: =I2*Balance!$B$2+J2*Balance!$B$3+K2*Balance!$B$4+L2*Balance!$B$5-M2*Balance!$B$6 -> 3 | T2: =IF(H2=0,"",S2/H2) -> 3 | U2: =IF(T2="","",IF(T2>$T$27*1.3,"HIGH",IF(T2<$T$27*0.7,"LOW","ok"))) -> ok
A3: C02 | B3: Sincere Answer | C3: 誠意ある答弁 | D3: Seii aru Tōben | E3: Earnest | F3: =IFERROR(INDEX(Suits!$B$2:$B$7,MATCH(E3,Suits!$A$2:$A$7,0)),"?") -> 誠実 | G3: Defend | H3: 1 | I3: 1 | J3: 0 | K3: 4 | L3: 0 | M3: 0 | N3: Any | O3: Gain 1. Guard 4 this turn. | P3: Guard 6. | Q3: Starter | R3: =IFERROR(INDEX(Balance!$B$12:$B$14,MATCH(Q3,Balance!$A$12:$A$14,0)),"") -> 0 | S3: =I3*Balance!$B$2+J3*Balance!$B$3+K3*Balance!$B$4+L3*Balance!$B$5-M3*Balance!$B$6 -> 3.4 | T3: =IF(H3=0,"",S3/H3) -> 3.4 | U3: =IF(T3="","",IF(T3>$T$27*1.3,"HIGH",IF(T3<$T$27*0.7,"LOW","ok"))) -> HIGH
A4: C03 | B4: Formal Apology | C4: 深々と頭を下げる | D4: Fukabuka to Atama o Sageru | E4: Earnest | F4: =IFERROR(INDEX(Suits!$B$2:$B$7,MATCH(E4,Suits!$A$2:$A$7,0)),"?") -> 誠実 | G4: Utility | H4: 2 | I4: 2 | J4: 0 | K4: 0 | L4: 0 | M4: -3 | N4: Any | O4: Gain 2. Reduce gaffe meter by 3. | P4: Also draw 1. | Q4: Tier 1 | R4: =IFERROR(INDEX(Balance!$B$12:$B$14,MATCH(Q4,Balance!$A$12:$A$14,0)),"") -> 60 | S4: =I4*Balance!$B$2+J4*Balance!$B$3+K4*Balance!$B$4+L4*Balance!$B$5-M4*Balance!$B$6 -> 6.5 | T4: =IF(H4=0,"",S4/H4) -> 3.25 | U4: =IF(T4="","",IF(T4>$T$27*1.3,"HIGH",IF(T4<$T$27*0.7,"LOW","ok"))) -> HIGH
A5: C04 | B5: Return to First Principles | C5: 初心表明 | D5: Shoshin Hyōmei | E5: Earnest | F5: =IFERROR(INDEX(Suits!$B$2:$B$7,MATCH(E5,Suits!$A$2:$A$7,0)),"?") -> 誠実 | G5: Gain | H5: 3 | I5: 6 | J5: 0 | K5: 0 | L5: 0 | M5: 0 | N5: Any | O5: Gain 6; +2 more if Kanban ≥ 60. | P5: Cost 2. | Q5: Tier 2 | R5: =IFERROR(INDEX(Balance!$B$12:$B$14,MATCH(Q5,Balance!$A$12:$A$14,0)),"") -> 120 | S5: =I5*Balance!$B$2+J5*Balance!$B$3+K5*Balance!$B$4+L5*Balance!$B$5-M5*Balance!$B$6 -> 6 | T5: =IF(H5=0,"",S5/H5) -> 2 | U5: =IF(T5="","",IF(T5>$T$27*1.3,"HIGH",IF(T5<$T$27*0.7,"LOW","ok"))) -> ok
A6: C05 | B6: Impassioned Speech | C6: 熱弁 | D6: Netsuben | E6: Emotional | F6: =IFERROR(INDEX(Suits!$B$2:$B$7,MATCH(E6,Suits!$A$2:$A$7,0)),"?") -> 情熱 | G6: Gain | H6: 2 | I6: 5 | J6: 0 | K6: 0 | L6: 0 | M6: 1 | N6: Any | O6: Gain 5. Gaffe +1. | P6: Gain 7. | Q6: Starter | R6: =IFERROR(INDEX(Balance!$B$12:$B$14,MATCH(Q6,Balance!$A$12:$A$14,0)),"") -> 0 | S6: =I6*Balance!$B$2+J6*Balance!$B$3+K6*Balance!$B$4+L6*Balance!$B$5-M6*Balance!$B$6 -> 3.5 | T6: =IF(H6=0,"",S6/H6) -> 1.75 | U6: =IF(T6="","",IF(T6>$T$27*1.3,"HIGH",IF(T6<$T$27*0.7,"LOW","ok"))) -> ok
A7: C06 | B7: Tearful Appeal | C7: 涙の訴え | D7: Namida no Uttae | E7: Emotional | F7: =IFERROR(INDEX(Suits!$B$2:$B$7,MATCH(E7,Suits!$A$2:$A$7,0)),"?") -> 情熱 | G7: Gain | H7: 2 | I7: 4 | J7: 0 | K7: 0 | L7: 0 | M7: 0 | N7: Constituents | O7: Gain 4; doubled if Constituents ≥ 50%. | P7: Gain 5. | Q7: Starter | R7: =IFERROR(INDEX(Balance!$B$12:$B$14,MATCH(Q7,Balance!$A$12:$A$14,0)),"") -> 0 | S7: =I7*Balance!$B$2+J7*Balance!$B$3+K7*Balance!$B$4+L7*Balance!$B$5-M7*Balance!$B$6 -> 4 | T7: =IF(H7=0,"",S7/H7) -> 2 | U7: =IF(T7="","",IF(T7>$T$27*1.3,"HIGH",IF(T7<$T$27*0.7,"LOW","ok"))) -> ok
A8: C07 | B8: Rousing Applause | C8: 拍手喝采 | D8: Hakushu Kassai | E8: Emotional | F8: =IFERROR(INDEX(Suits!$B$2:$B$7,MATCH(E8,Suits!$A$2:$A$7,0)),"?") -> 情熱 | G8: Utility | H8: 1 | I8: 2 | J8: 0 | K8: 0 | L8: 1 | M8: 0 | N8: Any | O8: Gain 2. Draw 1. | P8: Draw 2. | Q8: Tier 1 | R8: =IFERROR(INDEX(Balance!$B$12:$B$14,MATCH(Q8,Balance!$A$12:$A$14,0)),"") -> 60 | S8: =I8*Balance!$B$2+J8*Balance!$B$3+K8*Balance!$B$4+L8*Balance!$B$5-M8*Balance!$B$6 -> 4 | T8: =IF(H8=0,"",S8/H8) -> 4 | U8: =IF(T8="","",IF(T8>$T$27*1.3,"HIGH",IF(T8<$T$27*0.7,"LOW","ok"))) -> HIGH
A9: C08 | B9: Speech from the Soul | C9: 魂の演説 | D9: Tamashii no Enzetsu | E9: Emotional | F9: =IFERROR(INDEX(Suits!$B$2:$B$7,MATCH(E9,Suits!$A$2:$A$7,0)),"?") -> 情熱 | G9: Gain | H9: 3 | I9: 8 | J9: 0 | K9: 0 | L9: 0 | M9: 2 | N9: Any | O9: Gain 8. Gaffe +2. | P9: Gaffe +1. | Q9: Tier 2 | R9: =IFERROR(INDEX(Balance!$B$12:$B$14,MATCH(Q9,Balance!$A$12:$A$14,0)),"") -> 120 | S9: =I9*Balance!$B$2+J9*Balance!$B$3+K9*Balance!$B$4+L9*Balance!$B$5-M9*Balance!$B$6 -> 5 | T9: =IF(H9=0,"",S9/H9) -> 1.6666667 | U9: =IF(T9="","",IF(T9>$T$27*1.3,"HIGH",IF(T9<$T$27*0.7,"LOW","ok"))) -> LOW
A10: C09 | B10: Party Unity | C10: 党の結束 | D10: Tō no Kessoku | E10: Appeal | F10: =IFERROR(INDEX(Suits!$B$2:$B$7,MATCH(E10,Suits!$A$2:$A$7,0)),"?") -> 求心 | G10: Gain | H10: 1 | I10: 3 | J10: 0 | K10: 0 | L10: 0 | M10: 0 | N10: Loyalists | O10: Gain 3; +2 if Loyalists ≥ 50%. | P10: Gain 4. | Q10: Starter | R10: =IFERROR(INDEX(Balance!$B$12:$B$14,MATCH(Q10,Balance!$A$12:$A$14,0)),"") -> 0 | S10: =I10*Balance!$B$2+J10*Balance!$B$3+K10*Balance!$B$4+L10*Balance!$B$5-M10*Balance!$B$6 -> 3 | T10: =IF(H10=0,"",S10/H10) -> 3 | U10: =IF(T10="","",IF(T10>$T$27*1.3,"HIGH",IF(T10<$T$27*0.7,"LOW","ok"))) -> ok
A11: C10 | B11: Voice of the Hometown | C11: 地元の声 | D11: Jimoto no Koe | E11: Appeal | F11: =IFERROR(INDEX(Suits!$B$2:$B$7,MATCH(E11,Suits!$A$2:$A$7,0)),"?") -> 求心 | G11: Gain | H11: 1 | I11: 3 | J11: 0 | K11: 0 | L11: 0 | M11: 0 | N11: Constituents | O11: Gain 3; +2 if Constituents ≥ 50%. | P11: Gain 4. | Q11: Starter | R11: =IFERROR(INDEX(Balance!$B$12:$B$14,MATCH(Q11,Balance!$A$12:$A$14,0)),"") -> 0 | S11: =I11*Balance!$B$2+J11*Balance!$B$3+K11*Balance!$B$4+L11*Balance!$B$5-M11*Balance!$B$6 -> 3 | T11: =IF(H11=0,"",S11/H11) -> 3 | U11: =IF(T11="","",IF(T11>$T$27*1.3,"HIGH",IF(T11<$T$27*0.7,"LOW","ok"))) -> ok
A12: C11 | B12: Groundwork | C12: 根回し | D12: Nemawashi | E12: Appeal | F12: =IFERROR(INDEX(Suits!$B$2:$B$7,MATCH(E12,Suits!$A$2:$A$7,0)),"?") -> 求心 | G12: Buff | H12: 2 | I12: 2 | J12: 0 | K12: 0 | L12: 0 | M12: 0 | N12: Any | O12: Gain 2. Your next card this turn gets +2. | P12: Next card +3. | Q12: Tier 1 | R12: =IFERROR(INDEX(Balance!$B$12:$B$14,MATCH(Q12,Balance!$A$12:$A$14,0)),"") -> 60 | S12: =I12*Balance!$B$2+J12*Balance!$B$3+K12*Balance!$B$4+L12*Balance!$B$5-M12*Balance!$B$6 -> 2 | T12: =IF(H12=0,"",S12/H12) -> 1 | U12: =IF(T12="","",IF(T12>$T$27*1.3,"HIGH",IF(T12<$T$27*0.7,"LOW","ok"))) -> LOW
A13: C12 | B13: Head Count | C13: 票読み | D13: Hyōyomi | E13: Appeal | F13: =IFERROR(INDEX(Suits!$B$2:$B$7,MATCH(E13,Suits!$A$2:$A$7,0)),"?") -> 求心 | G13: Utility | H13: 2 | I13: 0 | J13: 0 | K13: 0 | L13: 2 | M13: 0 | N13: Any | O13: Draw 2. Reveal opponent's next intent. | P13: Cost 1. | Q13: Tier 1 | R13: =IFERROR(INDEX(Balance!$B$12:$B$14,MATCH(Q13,Balance!$A$12:$A$14,0)),"") -> 60 | S13: =I13*Balance!$B$2+J13*Balance!$B$3+K13*Balance!$B$4+L13*Balance!$B$5-M13*Balance!$B$6 -> 4 | T13: =IF(H13=0,"",S13/H13) -> 2 | U13: =IF(T13="","",IF(T13>$T$27*1.3,"HIGH",IF(T13<$T$27*0.7,"LOW","ok"))) -> ok
... A25: C24 | B25: Secret Pact | C25: 密約 | D25: Mitsuyaku | E25: Duplicitous | F25: =IFERROR(INDEX(Suits!$B$2:$B$7,MATCH(E25,Suits!$A$2:$A$7,0)),"?") -> 二枚舌 | G25: Gain | H25: 3 | I25: 7 | J25: 2 | K25: 0 | L25: 0 | M25: 3 | N25: Donors | O25: Gain 7. Opponent −2. Gaffe +3. | P25: Gaffe +2. | Q25: Tier 2 | R25: =IFERROR(INDEX(Balance!$B$12:$B$14,MATCH(Q25,Balance!$A$12:$A$14,0)),"") -> 120 | S25: =I25*Balance!$B$2+J25*Balance!$B$3+K25*Balance!$B$4+L25*Balance!$B$5-M25*Balance!$B$6 -> 4.9 | T25: =IF(H25=0,"",S25/H25) -> 1.6333333 | U25: =IF(T25="","",IF(T25>$T$27*1.3,"HIGH",IF(T25<$T$27*0.7,"LOW","ok"))) -> LOW
A27: Avg Power/Cost | T27: =AVERAGE(T2:T25) -> 2.43125
A28: Flag if P/C > avg × 1.3 or < avg × 0.7 — candidates to rebalance

Sheet CardStage
A1: Card ID | B1: Name | C1: Suit | D1: ST01 | E1: ST02 | F1: ST03 | G1: ST04 | H1: ST05 | I1: ST06 | J1: ST08
A2: =Cards!A2 -> C01 | B2: =Cards!B2 -> Record of Service | C2: =Cards!E2 -> Earnest | D2: =ROUND(Cards!$S2*INDEX(Affinity!$B$2:$H$7,MATCH($C2,Affinity!$A$2:$A$7,0),MATCH(D$1,Affinity!$B$1:$H$1,0)),1) -> 3 | E2: =ROUND(Cards!$S2*INDEX(Affinity!$B$2:$H$7,MATCH($C2,Affinity!$A$2:$A$7,0),MATCH(E$1,Affinity!$B$1:$H$1,0)),1) -> 3 | F2: =ROUND(Cards!$S2*INDEX(Affinity!$B$2:$H$7,MATCH($C2,Affinity!$A$2:$A$7,0),MATCH(F$1,Affinity!$B$1:$H$1,0)),1) -> 3.3 | G2: =ROUND(Cards!$S2*INDEX(Affinity!$B$2:$H$7,MATCH($C2,Affinity!$A$2:$A$7,0),MATCH(G$1,Affinity!$B$1:$H$1,0)),1) -> 3.6 | H2: =ROUND(Cards!$S2*INDEX(Affinity!$B$2:$H$7,MATCH($C2,Affinity!$A$2:$A$7,0),MATCH(H$1,Affinity!$B$1:$H$1,0)),1) -> 3.6 | I2: =ROUND(Cards!$S2*INDEX(Affinity!$B$2:$H$7,MATCH($C2,Affinity!$A$2:$A$7,0),MATCH(I$1,Affinity!$B$1:$H$1,0)),1) -> 3.3 | J2: =ROUND(Cards!$S2*INDEX(Affinity!$B$2:$H$7,MATCH($C2,Affinity!$A$2:$A$7,0),MATCH(J$1,Affinity!$B$1:$H$1,0)),1) -> 3.6
A3: =Cards!A3 -> C02 | B3: =Cards!B3 -> Sincere Answer | C3: =Cards!E3 -> Earnest | D3: =ROUND(Cards!$S3*INDEX(Affinity!$B$2:$H$7,MATCH($C3,Affinity!$A$2:$A$7,0),MATCH(D$1,Affinity!$B$1:$H$1,0)),1) -> 3.4 | E3: =ROUND(Cards!$S3*INDEX(Affinity!$B$2:$H$7,MATCH($C3,Affinity!$A$2:$A$7,0),MATCH(E$1,Affinity!$B$1:$H$1,0)),1) -> 3.4 | F3: =ROUND(Cards!$S3*INDEX(Affinity!$B$2:$H$7,MATCH($C3,Affinity!$A$2:$A$7,0),MATCH(F$1,Affinity!$B$1:$H$1,0)),1) -> 3.7 | G3: =ROUND(Cards!$S3*INDEX(Affinity!$B$2:$H$7,MATCH($C3,Affinity!$A$2:$A$7,0),MATCH(G$1,Affinity!$B$1:$H$1,0)),1) -> 4.1 | H3: =ROUND(Cards!$S3*INDEX(Affinity!$B$2:$H$7,MATCH($C3,Affinity!$A$2:$A$7,0),MATCH(H$1,Affinity!$B$1:$H$1,0)),1) -> 4.1 | I3: =ROUND(Cards!$S3*INDEX(Affinity!$B$2:$H$7,MATCH($C3,Affinity!$A$2:$A$7,0),MATCH(I$1,Affinity!$B$1:$H$1,0)),1) -> 3.7 | J3: =ROUND(Cards!$S3*INDEX(Affinity!$B$2:$H$7,MATCH($C3,Affinity!$A$2:$A$7,0),MATCH(J$1,Affinity!$B$1:$H$1,0)),1) -> 4.1
A4: =Cards!A4 -> C03 | B4: =Cards!B4 -> Formal Apology | C4: =Cards!E4 -> Earnest | D4: =ROUND(Cards!$S4*INDEX(Affinity!$B$2:$H$7,MATCH($C4,Affinity!$A$2:$A$7,0),MATCH(D$1,Affinity!$B$1:$H$1,0)),1) -> 6.5 | E4: =ROUND(Cards!$S4*INDEX(Affinity!$B$2:$H$7,MATCH($C4,Affinity!$A$2:$A$7,0),MATCH(E$1,Affinity!$B$1:$H$1,0)),1) -> 6.5 | F4: =ROUND(Cards!$S4*INDEX(Affinity!$B$2:$H$7,MATCH($C4,Affinity!$A$2:$A$7,0),MATCH(F$1,Affinity!$B$1:$H$1,0)),1) -> 7.2 | G4: =ROUND(Cards!$S4*INDEX(Affinity!$B$2:$H$7,MATCH($C4,Affinity!$A$2:$A$7,0),MATCH(G$1,Affinity!$B$1:$H$1,0)),1) -> 7.8 | H4: =ROUND(Cards!$S4*INDEX(Affinity!$B$2:$H$7,MATCH($C4,Affinity!$A$2:$A$7,0),MATCH(H$1,Affinity!$B$1:$H$1,0)),1) -> 7.8 | I4: =ROUND(Cards!$S4*INDEX(Affinity!$B$2:$H$7,MATCH($C4,Affinity!$A$2:$A$7,0),MATCH(I$1,Affinity!$B$1:$H$1,0)),1) -> 7.2 | J4: =ROUND(Cards!$S4*INDEX(Affinity!$B$2:$H$7,MATCH($C4,Affinity!$A$2:$A$7,0),MATCH(J$1,Affinity!$B$1:$H$1,0)),1) -> 7.8
A5: =Cards!A5 -> C04 | B5: =Cards!B5 -> Return to First Principles | C5: =Cards!E5 -> Earnest | D5: =ROUND(Cards!$S5*INDEX(Affinity!$B$2:$H$7,MATCH($C5,Affinity!$A$2:$A$7,0),MATCH(D$1,Affinity!$B$1:$H$1,0)),1) -> 6 | E5: =ROUND(Cards!$S5*INDEX(Affinity!$B$2:$H$7,MATCH($C5,Affinity!$A$2:$A$7,0),MATCH(E$1,Affinity!$B$1:$H$1,0)),1) -> 6 | F5: =ROUND(Cards!$S5*INDEX(Affinity!$B$2:$H$7,MATCH($C5,Affinity!$A$2:$A$7,0),MATCH(F$1,Affinity!$B$1:$H$1,0)),1) -> 6.6 | G5: =ROUND(Cards!$S5*INDEX(Affinity!$B$2:$H$7,MATCH($C5,Affinity!$A$2:$A$7,0),MATCH(G$1,Affinity!$B$1:$H$1,0)),1) -> 7.2 | H5: =ROUND(Cards!$S5*INDEX(Affinity!$B$2:$H$7,MATCH($C5,Affinity!$A$2:$A$7,0),MATCH(H$1,Affinity!$B$1:$H$1,0)),1) -> 7.2 | I5: =ROUND(Cards!$S5*INDEX(Affinity!$B$2:$H$7,MATCH($C5,Affinity!$A$2:$A$7,0),MATCH(I$1,Affinity!$B$1:$H$1,0)),1) -> 6.6 | J5: =ROUND(Cards!$S5*INDEX(Affinity!$B$2:$H$7,MATCH($C5,Affinity!$A$2:$A$7,0),MATCH(J$1,Affinity!$B$1:$H$1,0)),1) -> 7.2
A6: =Cards!A6 -> C05 | B6: =Cards!B6 -> Impassioned Speech | C6: =Cards!E6 -> Emotional | D6: =ROUND(Cards!$S6*INDEX(Affinity!$B$2:$H$7,MATCH($C6,Affinity!$A$2:$A$7,0),MATCH(D$1,Affinity!$B$1:$H$1,0)),1) -> 2.8 | E6: =ROUND(Cards!$S6*INDEX(Affinity!$B$2:$H$7,MATCH($C6,Affinity!$A$2:$A$7,0),MATCH(E$1,Affinity!$B$1:$H$1,0)),1) -> 3.9 | F6: =ROUND(Cards!$S6*INDEX(Affinity!$B$2:$H$7,MATCH($C6,Affinity!$A$2:$A$7,0),MATCH(F$1,Affinity!$B$1:$H$1,0)),1) -> 3.5 | G6: =ROUND(Cards!$S6*INDEX(Affinity!$B$2:$H$7,MATCH($C6,Affinity!$A$2:$A$7,0),MATCH(G$1,Affinity!$B$1:$H$1,0)),1) -> 3.2 | H6: =ROUND(Cards!$S6*INDEX(Affinity!$B$2:$H$7,MATCH($C6,Affinity!$A$2:$A$7,0),MATCH(H$1,Affinity!$B$1:$H$1,0)),1) -> 4.6 | I6: =ROUND(Cards!$S6*INDEX(Affinity!$B$2:$H$7,MATCH($C6,Affinity!$A$2:$A$7,0),MATCH(I$1,Affinity!$B$1:$H$1,0)),1) -> 3.5 | J6: =ROUND(Cards!$S6*INDEX(Affinity!$B$2:$H$7,MATCH($C6,Affinity!$A$2:$A$7,0),MATCH(J$1,Affinity!$B$1:$H$1,0)),1) -> 3.2
A7: =Cards!A7 -> C06 | B7: =Cards!B7 -> Tearful Appeal | C7: =Cards!E7 -> Emotional | D7: =ROUND(Cards!$S7*INDEX(Affinity!$B$2:$H$7,MATCH($C7,Affinity!$A$2:$A$7,0),MATCH(D$1,Affinity!$B$1:$H$1,0)),1) -> 3.2 | E7: =ROUND(Cards!$S7*INDEX(Affinity!$B$2:$H$7,MATCH($C7,Affinity!$A$2:$A$7,0),MATCH(E$1,Affinity!$B$1:$H$1,0)),1) -> 4.4 | F7: =ROUND(Cards!$S7*INDEX(Affinity!$B$2:$H$7,MATCH($C7,Affinity!$A$2:$A$7,0),MATCH(F$1,Affinity!$B$1:$H$1,0)),1) -> 4 | G7: =ROUND(Cards!$S7*INDEX(Affinity!$B$2:$H$7,MATCH($C7,Affinity!$A$2:$A$7,0),MATCH(G$1,Affinity!$B$1:$H$1,0)),1) -> 3.6 | H7: =ROUND(Cards!$S7*INDEX(Affinity!$B$2:$H$7,MATCH($C7,Affinity!$A$2:$A$7,0),MATCH(H$1,Affinity!$B$1:$H$1,0)),1) -> 5.2 | I7: =ROUND(Cards!$S7*INDEX(Affinity!$B$2:$H$7,MATCH($C7,Affinity!$A$2:$A$7,0),MATCH(I$1,Affinity!$B$1:$H$1,0)),1) -> 4 | J7: =ROUND(Cards!$S7*INDEX(Affinity!$B$2:$H$7,MATCH($C7,Affinity!$A$2:$A$7,0),MATCH(J$1,Affinity!$B$1:$H$1,0)),1) -> 3.6
A8: =Cards!A8 -> C07 | B8: =Cards!B8 -> Rousing Applause | C8: =Cards!E8 -> Emotional | D8: =ROUND(Cards!$S8*INDEX(Affinity!$B$2:$H$7,MATCH($C8,Affinity!$A$2:$A$7,0),MATCH(D$1,Affinity!$B$1:$H$1,0)),1) -> 3.2 | E8: =ROUND(Cards!$S8*INDEX(Affinity!$B$2:$H$7,MATCH($C8,Affinity!$A$2:$A$7,0),MATCH(E$1,Affinity!$B$1:$H$1,0)),1) -> 4.4 | F8: =ROUND(Cards!$S8*INDEX(Affinity!$B$2:$H$7,MATCH($C8,Affinity!$A$2:$A$7,0),MATCH(F$1,Affinity!$B$1:$H$1,0)),1) -> 4 | G8: =ROUND(Cards!$S8*INDEX(Affinity!$B$2:$H$7,MATCH($C8,Affinity!$A$2:$A$7,0),MATCH(G$1,Affinity!$B$1:$H$1,0)),1) -> 3.6 | H8: =ROUND(Cards!$S8*INDEX(Affinity!$B$2:$H$7,MATCH($C8,Affinity!$A$2:$A$7,0),MATCH(H$1,Affinity!$B$1:$H$1,0)),1) -> 5.2 | I8: =ROUND(Cards!$S8*INDEX(Affinity!$B$2:$H$7,MATCH($C8,Affinity!$A$2:$A$7,0),MATCH(I$1,Affinity!$B$1:$H$1,0)),1) -> 4 | J8: =ROUND(Cards!$S8*INDEX(Affinity!$B$2:$H$7,MATCH($C8,Affinity!$A$2:$A$7,0),MATCH(J$1,Affinity!$B$1:$H$1,0)),1) -> 3.6
A9: =Cards!A9 -> C08 | B9: =Cards!B9 -> Speech from the Soul | C9: =Cards!E9 -> Emotional | D9: =ROUND(Cards!$S9*INDEX(Affinity!$B$2:$H$7,MATCH($C9,Affinity!$A$2:$A$7,0),MATCH(D$1,Affinity!$B$1:$H$1,0)),1) -> 4 | E9: =ROUND(Cards!$S9*INDEX(Affinity!$B$2:$H$7,MATCH($C9,Affinity!$A$2:$A$7,0),MATCH(E$1,Affinity!$B$1:$H$1,0)),1) -> 5.5 | F9: =ROUND(Cards!$S9*INDEX(Affinity!$B$2:$H$7,MATCH($C9,Affinity!$A$2:$A$7,0),MATCH(F$1,Affinity!$B$1:$H$1,0)),1) -> 5 | G9: =ROUND(Cards!$S9*INDEX(Affinity!$B$2:$H$7,MATCH($C9,Affinity!$A$2:$A$7,0),MATCH(G$1,Affinity!$B$1:$H$1,0)),1) -> 4.5 | H9: =ROUND(Cards!$S9*INDEX(Affinity!$B$2:$H$7,MATCH($C9,Affinity!$A$2:$A$7,0),MATCH(H$1,Affinity!$B$1:$H$1,0)),1) -> 6.5 | I9: =ROUND(Cards!$S9*INDEX(Affinity!$B$2:$H$7,MATCH($C9,Affinity!$A$2:$A$7,0),MATCH(I$1,Affinity!$B$1:$H$1,0)),1) -> 5 | J9: =ROUND(Cards!$S9*INDEX(Affinity!$B$2:$H$7,MATCH($C9,Affinity!$A$2:$A$7,0),MATCH(J$1,Affinity!$B$1:$H$1,0)),1) -> 4.5
A10: =Cards!A10 -> C09 | B10: =Cards!B10 -> Party Unity | C10: =Cards!E10 -> Appeal | D10: =ROUND(Cards!$S10*INDEX(Affinity!$B$2:$H$7,MATCH($C10,Affinity!$A$2:$A$7,0),MATCH(D$1,Affinity!$B$1:$H$1,0)),1) -> 3 | E10: =ROUND(Cards!$S10*INDEX(Affinity!$B$2:$H$7,MATCH($C10,Affinity!$A$2:$A$7,0),MATCH(E$1,Affinity!$B$1:$H$1,0)),1) -> 3.6 | F10: =ROUND(Cards!$S10*INDEX(Affinity!$B$2:$H$7,MATCH($C10,Affinity!$A$2:$A$7,0),MATCH(F$1,Affinity!$B$1:$H$1,0)),1) -> 3.8 | G10: =ROUND(Cards!$S10*INDEX(Affinity!$B$2:$H$7,MATCH($C10,Affinity!$A$2:$A$7,0),MATCH(G$1,Affinity!$B$1:$H$1,0)),1) -> 2.7 | H10: =ROUND(Cards!$S10*INDEX(Affinity!$B$2:$H$7,MATCH($C10,Affinity!$A$2:$A$7,0),MATCH(H$1,Affinity!$B$1:$H$1,0)),1) -> 3.3 | I10: =ROUND(Cards!$S10*INDEX(Affinity!$B$2:$H$7,MATCH($C10,Affinity!$A$2:$A$7,0),MATCH(I$1,Affinity!$B$1:$H$1,0)),1) -> 3 | J10: =ROUND(Cards!$S10*INDEX(Affinity!$B$2:$H$7,MATCH($C10,Affinity!$A$2:$A$7,0),MATCH(J$1,Affinity!$B$1:$H$1,0)),1) -> 3.9
A11: =Cards!A11 -> C10 | B11: =Cards!B11 -> Voice of the Hometown | C11: =Cards!E11 -> Appeal | D11: =ROUND(Cards!$S11*INDEX(Affinity!$B$2:$H$7,MATCH($C11,Affinity!$A$2:$A$7,0),MATCH(D$1,Affinity!$B$1:$H$1,0)),1) -> 3 | E11: =ROUND(Cards!$S11*INDEX(Affinity!$B$2:$H$7,MATCH($C11,Affinity!$A$2:$A$7,0),MATCH(E$1,Affinity!$B$1:$H$1,0)),1) -> 3.6 | F11: =ROUND(Cards!$S11*INDEX(Affinity!$B$2:$H$7,MATCH($C11,Affinity!$A$2:$A$7,0),MATCH(F$1,Affinity!$B$1:$H$1,0)),1) -> 3.8 | G11: =ROUND(Cards!$S11*INDEX(Affinity!$B$2:$H$7,MATCH($C11,Affinity!$A$2:$A$7,0),MATCH(G$1,Affinity!$B$1:$H$1,0)),1) -> 2.7 | H11: =ROUND(Cards!$S11*INDEX(Affinity!$B$2:$H$7,MATCH($C11,Affinity!$A$2:$A$7,0),MATCH(H$1,Affinity!$B$1:$H$1,0)),1) -> 3.3 | I11: =ROUND(Cards!$S11*INDEX(Affinity!$B$2:$H$7,MATCH($C11,Affinity!$A$2:$A$7,0),MATCH(I$1,Affinity!$B$1:$H$1,0)),1) -> 3 | J11: =ROUND(Cards!$S11*INDEX(Affinity!$B$2:$H$7,MATCH($C11,Affinity!$A$2:$A$7,0),MATCH(J$1,Affinity!$B$1:$H$1,0)),1) -> 3.9
A12: =Cards!A12 -> C11 | B12: =Cards!B12 -> Groundwork | C12: =Cards!E12 -> Appeal | D12: =ROUND(Cards!$S12*INDEX(Affinity!$B$2:$H$7,MATCH($C12,Affinity!$A$2:$A$7,0),MATCH(D$1,Affinity!$B$1:$H$1,0)),1) -> 2 | E12: =ROUND(Cards!$S12*INDEX(Affinity!$B$2:$H$7,MATCH($C12,Affinity!$A$2:$A$7,0),MATCH(E$1,Affinity!$B$1:$H$1,0)),1) -> 2.4 | F12: =ROUND(Cards!$S12*INDEX(Affinity!$B$2:$H$7,MATCH($C12,Affinity!$A$2:$A$7,0),MATCH(F$1,Affinity!$B$1:$H$1,0)),1) -> 2.5 | G12: =ROUND(Cards!$S12*INDEX(Affinity!$B$2:$H$7,MATCH($C12,Affinity!$A$2:$A$7,0),MATCH(G$1,Affinity!$B$1:$H$1,0)),1) -> 1.8 | H12: =ROUND(Cards!$S12*INDEX(Affinity!$B$2:$H$7,MATCH($C12,Affinity!$A$2:$A$7,0),MATCH(H$1,Affinity!$B$1:$H$1,0)),1) -> 2.2 | I12: =ROUND(Cards!$S12*INDEX(Affinity!$B$2:$H$7,MATCH($C12,Affinity!$A$2:$A$7,0),MATCH(I$1,Affinity!$B$1:$H$1,0)),1) -> 2 | J12: =ROUND(Cards!$S12*INDEX(Affinity!$B$2:$H$7,MATCH($C12,Affinity!$A$2:$A$7,0),MATCH(J$1,Affinity!$B$1:$H$1,0)),1) -> 2.6
A13: =Cards!A13 -> C12 | B13: =Cards!B13 -> Head Count | C13: =Cards!E13 -> Appeal | D13: =ROUND(Cards!$S13*INDEX(Affinity!$B$2:$H$7,MATCH($C13,Affinity!$A$2:$A$7,0),MATCH(D$1,Affinity!$B$1:$H$1,0)),1) -> 4 | E13: =ROUND(Cards!$S13*INDEX(Affinity!$B$2:$H$7,MATCH($C13,Affinity!$A$2:$A$7,0),MATCH(E$1,Affinity!$B$1:$H$1,0)),1) -> 4.8 | F13: =ROUND(Cards!$S13*INDEX(Affinity!$B$2:$H$7,MATCH($C13,Affinity!$A$2:$A$7,0),MATCH(F$1,Affinity!$B$1:$H$1,0)),1) -> 5 | G13: =ROUND(Cards!$S13*INDEX(Affinity!$B$2:$H$7,MATCH($C13,Affinity!$A$2:$A$7,0),MATCH(G$1,Affinity!$B$1:$H$1,0)),1) -> 3.6 | H13: =ROUND(Cards!$S13*INDEX(Affinity!$B$2:$H$7,MATCH($C13,Affinity!$A$2:$A$7,0),MATCH(H$1,Affinity!$B$1:$H$1,0)),1) -> 4.4 | I13: =ROUND(Cards!$S13*INDEX(Affinity!$B$2:$H$7,MATCH($C13,Affinity!$A$2:$A$7,0),MATCH(I$1,Affinity!$B$1:$H$1,0)),1) -> 4 | J13: =ROUND(Cards!$S13*INDEX(Affinity!$B$2:$H$7,MATCH($C13,Affinity!$A$2:$A$7,0),MATCH(J$1,Affinity!$B$1:$H$1,0)),1) -> 5.2
... A25: =Cards!A25 -> C24 | B25: =Cards!B25 -> Secret Pact | C25: =Cards!E25 -> Duplicitous | D25: =ROUND(Cards!$S25*INDEX(Affinity!$B$2:$H$7,MATCH($C25,Affinity!$A$2:$A$7,0),MATCH(D$1,Affinity!$B$1:$H$1,0)),1) -> 5.4 | E25: =ROUND(Cards!$S25*INDEX(Affinity!$B$2:$H$7,MATCH($C25,Affinity!$A$2:$A$7,0),MATCH(E$1,Affinity!$B$1:$H$1,0)),1) -> 4.9 | F25: =ROUND(Cards!$S25*INDEX(Affinity!$B$2:$H$7,MATCH($C25,Affinity!$A$2:$A$7,0),MATCH(F$1,Affinity!$B$1:$H$1,0)),1) -> 5.4 | G25: =ROUND(Cards!$S25*INDEX(Affinity!$B$2:$H$7,MATCH($C25,Affinity!$A$2:$A$7,0),MATCH(G$1,Affinity!$B$1:$H$1,0)),1) -> 3.4 | H25: =ROUND(Cards!$S25*INDEX(Affinity!$B$2:$H$7,MATCH($C25,Affinity!$A$2:$A$7,0),MATCH(H$1,Affinity!$B$1:$H$1,0)),1) -> 4.4 | I25: =ROUND(Cards!$S25*INDEX(Affinity!$B$2:$H$7,MATCH($C25,Affinity!$A$2:$A$7,0),MATCH(I$1,Affinity!$B$1:$H$1,0)),1) -> 3.9 | J25: =ROUND(Cards!$S25*INDEX(Affinity!$B$2:$H$7,MATCH($C25,Affinity!$A$2:$A$7,0),MATCH(J$1,Affinity!$B$1:$H$1,0)),1) -> 4.9
B26: Stage average | D26: =AVERAGE(D2:D25) -> 4.1375 | E26: =AVERAGE(E2:E25) -> 4.5125 | F26: =AVERAGE(F2:F25) -> 4.0958333 | G26: =AVERAGE(G2:G25) -> 4.0125 | H26: =AVERAGE(H2:H25) -> 4.35 | I26: =AVERAGE(I2:I25) -> 4.35 | J26: =AVERAGE(J2:J25) -> 4.1083333

Sheet Segments
A1: Segment ID | B1: Segment (EN) | C1: Segment (JP) | D1: Romaji | E1: Description
A2: SG01 | B2: Press | C2: 報道陣 | D2: Hōdōjin | E2: Reporters, editors, camera crews
A3: SG02 | B3: Loyalists | C3: 党員 | D3: Tōin | E3: Party members and whips
A4: SG03 | B4: Constituents | C4: 有権者 | D4: Yūkensha | E4: Voters of the protagonist's district and the general public
A5: SG04 | B5: Donors | C5: 支援者 | D5: Shiensha | E5: Backers, business associations, Kōenkai members
A6: SG05 | B6: Bureaucrats | C6: 官僚 | D6: Kanryō | E6: Ministry officials and committee staff

Sheet Modifiers
A1: Mod ID | B1: Category | C1: Category (JP) | D1: Name (EN) | E1: Name (JP) | F1: Romaji | G1: Trigger segment | H1: Trigger min % | I1: Effect | J1: Magnitude | K1: Kaban cost | L1: Available to | M1: Source booster
A2: M01 | B2: Kōenkai | C2: 後援会 | D2: Local Support Association | E2: 地元後援会 | F2: Jimoto Kōenkai | G2: Constituents | H2: 0.3 | I2: +Magnitude player start support | J2: 3 | K2: 20 | L2: Both | M2: BO03
A3: M02 | B3: Kōenkai | C3: 後援会 | D3: Business Backers' Circle | E3: 経済人の会 | F3: Keizaijin no Kai | G3: Donors | H3: 0.1 | I3: +Magnitude Kaban after each stage win | J3: 5 | K3: 30 | L3: Both | M3: BO05
A4: M03 | B4: Bankisha | C4: 番記者 | D4: Friendly Beat Reporter | E4: 好意的な番記者 | F4: Kōiteki na Bankisha | G4: Press | H4: 0.2 | I4: −Magnitude starting gaffe meter | J4: 1 | K4: 20 | L4: Both | M4: BO08
A5: M04 | B5: Bankisha | C5: 番記者 | D5: Editorial Board Backing | E5: 論説委員の支持 | F5: Ronsetsu Iin no Shiji | G5: Press | H5: 0.2 | I5: +Magnitude player start support | J5: 3 | K5: 40 | L5: Both | M5: BO08
A6: M05 | B6: Dantai | C6: 団体 | D6: Agricultural Cooperatives | E6: 農協 | F6: Nōkyō | G6: Constituents | H6: 0.3 | I6: −Magnitude opp start support on bills tagged Rural Focus | J6: 5 | K6: 30 | L6: Both | M6: BO10
A7: M06 | B7: Dantai | C7: 団体 | D7: Labor Federation | E7: 労働組合連合 | F7: Rōdō Kumiai Rengō | G7: Loyalists | H7: 0.3 | I7: +Magnitude player start support in Caucus/Floor | J7: 4 | K7: 30 | L7: Both | M7: BO09
A8: M07 | B8: Debuff | C8: 逆風 | D8: Scandal Coverage | E8: スキャンダル報道 | F8: Sukyandaru Hōdō | G8: Press | H8: 0.1 | I8: +Magnitude target's starting gaffe meter | J8: 2 | L8: Opponent | M8: —
A9: M08 | B9: Debuff | C9: 逆風 | D9: Faction Rebellion | E9: 造反 | F9: Zōhan | G9: Loyalists | H9: 0.3 | I9: −Magnitude target's start support | J9: 4 | L9: Opponent | M9: —
A10: M09 | B10: Party | C10: 党 | D10: Party Backing | E10: 党の後押し | F10: Tō no Atooshi | G10: Loyalists | I10: While Party support > 75: +Magnitude start support in Caucus & Floor | J10: 3 | L10: Both | M10: Party support (meta)
A11: M10 | B11: Party | C11: 党 | D11: Cold Shoulder | E11: 党内の冷遇 | F11: Tōnai no Reigū | G11: Loyalists | I11: While Party support < 50: −Magnitude start support in Caucus & Floor; −1 hand size on Floor | J11: 3 | L11: Both | M11: Party support (meta)
A12: M11 | B12: Party | C12: 党 | D12: Official Endorsement | E12: 党公認 | F12: Tō Kōnin | G12: Loyalists | I12: Negates Cold Shoulder (M10); +Magnitude Kaban per module | J12: 5 | K12: 40 | L12: Both | M12: BO01
A13: M12 | B13: Party | C13: 党 | D13: Faction Patronage | E13: 派閥の庇護 | F13: Habatsu no Higo | G13: Loyalists | I13: +Magnitude Party support per module; Party Backing triggers 5 points sooner | J13: 3 | K13: 30 | L13: Both | M13: BO02
A14: M13 | B14: Local | C14: 地元 | D14: Mayors' Endorsement | E14: 首長の推薦 | F14: Shuchō no Suisen | G14: Constituents | H14: 0.3 | I14: +Magnitude Jiban per module win; +1 start member lean in committee on local bills | J14: 3 | K14: 30 | L14: Both | M14: BO04
A15: M14 | B15: Local | C15: 地元 | D15: Community Canvass | E15: 町内会の支援 | F15: Chōnaikai no Shien | G15: Constituents | H15: 0.5 | I15: +Magnitude start support in Town Hall; Jiban losses halved | J15: 4 | K15: 20 | L15: Both | M15: BO06
A16: M15 | B16: Dantai | C16: 団体 | D16: Fishing Fleet Support | E16: 漁協の支援 | F16: Gyokyō no Shien | G16: Constituents | H16: 0.3 | I16: −Magnitude opp start support on Environment-tagged bills (fisheries topic TBD) | J16: 5 | K16: 30 | L16: Both | M16: BO07

Sheet Boosters
A1: Booster ID | B1: Organization (EN) | C1: Organization (JP) | D1: Romaji | E1: Tier | F1: Boosts | G1: Linked modifiers | H1: Modifier count
A2: BO01 | B2: Party Headquarters | C2: 党本部 | D2: Tōhonbu | E2: Party | F2: Endorsement, funds; protection from Cold Shoulder (M10) | G2: M11 | H2: =COUNTIF(Modifiers!$M$2:$M$100,A2) -> 1
A3: BO02 | B3: Party Faction | C3: 派閥 | D3: Habatsu | E3: Party | F3: Party support, patronage, small funds | G3: M12 | H3: =COUNTIF(Modifiers!$M$2:$M$100,A3) -> 1
A4: BO03 | B4: Local Kōenkai | C4: 後援会 | D4: Kōenkai | E4: Constituency | F4: Start support when constituents present; donations | G4: M01 | H4: =COUNTIF(Modifiers!$M$2:$M$100,A4) -> 1
A5: BO04 | B5: Mayors' Network | C5: 市町村長会 | D5: Shichōsonchō-kai | E5: Constituency | F5: Jiban gains; standing on local bills | G5: M13 | H5: =COUNTIF(Modifiers!$M$2:$M$100,A5) -> 1
A6: BO05 | B6: Chamber of Commerce | C6: 商工会議所 | D6: Shōkō Kaigisho | E6: National | F6: Funds; donor-audience bonus | G6: M02 | H6: =COUNTIF(Modifiers!$M$2:$M$100,A6) -> 1
A7: BO06 | B7: Neighborhood Associations | C7: 町内会 | D7: Chōnaikai | E7: Constituency | F7: Town hall bonus; slows Jiban loss | G7: M14 | H7: =COUNTIF(Modifiers!$M$2:$M$100,A7) -> 1
A8: BO07 | B8: Fisheries Cooperative | C8: 漁協 | D8: Gyokyō | E8: Constituency | F8: Fisheries, environment, and Kuril bills | G8: M15 | H8: =COUNTIF(Modifiers!$M$2:$M$100,A8) -> 1
A9: BO08 | B9: National Media | C9: 全国紙 | D9: Zenkokushi | E9: National | F9: Press tone; Kanban | G9: M03, M04 | H9: =COUNTIF(Modifiers!$M$2:$M$100,A9) -> 2
A10: BO09 | B10: Labor Federation | C10: 労働組合連合 | D10: Rōdō Kumiai Rengō | E10: National | F10: Loyalists; caucus and floor stages | G10: M06 | H10: =COUNTIF(Modifiers!$M$2:$M$100,A10) -> 1
A11: BO10 | B11: Agricultural Cooperatives | C11: 農協 | D11: Nōkyō | E11: National | F11: Rural Focus bills | G11: M05 | H11: =COUNTIF(Modifiers!$M$2:$M$100,A11) -> 1
D13: Tier balance
D14: Party | E14: =COUNTIF($E$2:$E$11,D14) -> 2
D15: Constituency | E15: =COUNTIF($E$2:$E$11,D15) -> 4
D16: National | E16: =COUNTIF($E$2:$E$11,D16) -> 4

Sheet Opponents
A1: Opp ID | B1: Name | C1: Party | D1: Committee | E1: Positioning | F1: Element 1 | G1: Element 2 | H1: Primary suit | I1: Secondary suit | J1: Deck size | K1: Primary cards | L1: Secondary cards | M1: Other cards | N1: AI style [proposed] | O1: Loadout mods | P1: Source
A2: OP01 | B2: Barclay Brigham | C2: Keizaijiyuutou | D2: National Assembly | E2: Technocratic | F2: Earnest | G2: Data Driven | H2: =IFERROR(INDEX(Suits!$B$2:$B$7,MATCH(F2,Suits!$A$2:$A$7,0)),"?") -> 誠実 | I2: =IFERROR(INDEX(Suits!$B$2:$B$7,MATCH(G2,Suits!$A$2:$A$7,0)),"?") -> 実証 | J2: =Balance!$B$8 -> 12 | K2: =ROUND(J2*Balance!$B$9,0) -> 6 | L2: =ROUND(J2*Balance!$B$10,0) -> 4 | M2: =J2-K2-L2 -> 2 | N2: Methodical: builds guard, then refutes with evidence. | O2: M04 | P2: Canon: Lore Databook, October_2018_Politicians (cols B–G)
A3: OP02 | B3: Yuriko Mayeda | C3: Frontier Party | D3: Construction and Development | E3: Populist | F3: Emotional | G3: Divisive | H3: =IFERROR(INDEX(Suits!$B$2:$B$7,MATCH(F3,Suits!$A$2:$A$7,0)),"?") -> 情熱 | I3: =IFERROR(INDEX(Suits!$B$2:$B$7,MATCH(G3,Suits!$A$2:$A$7,0)),"?") -> 分断 | J3: =Balance!$B$8 -> 12 | K3: =ROUND(J3*Balance!$B$9,0) -> 6 | L3: =ROUND(J3*Balance!$B$10,0) -> 4 | M3: =J3-K3-L3 -> 2 | N3: Aggressive bursts; accepts gaffe risk. | O3: M01 | P3: Canon: Lore Databook, October_2018_Politicians (cols B–G)
A4: OP03 | B4: Masato Maruyama | C4: Country Initiative | D4: National Assembly | E4: Identity | F4: Duplicitous | G4: Divisive | H4: =IFERROR(INDEX(Suits!$B$2:$B$7,MATCH(F4,Suits!$A$2:$A$7,0)),"?") -> 二枚舌 | I4: =IFERROR(INDEX(Suits!$B$2:$B$7,MATCH(G4,Suits!$A$2:$A$7,0)),"?") -> 分断 | J4: =Balance!$B$8 -> 12 | K4: =ROUND(J4*Balance!$B$9,0) -> 6 | L4: =ROUND(J4*Balance!$B$10,0) -> 4 | M4: =J4-K4-L4 -> 2 | N4: Evasive guards, then polarizing strikes. | O4: M08 | P4: Canon: Lore Databook, October_2018_Politicians (cols B–G)
A5: OP04 | B5: Kitahime Haibi | C5: Five Point Independents | D5: Finance | E5: Free Markets | F5: Data Driven | G5: Appeal | H5: =IFERROR(INDEX(Suits!$B$2:$B$7,MATCH(F5,Suits!$A$2:$A$7,0)),"?") -> 実証 | I5: =IFERROR(INDEX(Suits!$B$2:$B$7,MATCH(G5,Suits!$A$2:$A$7,0)),"?") -> 求心 | J5: =Balance!$B$8 -> 12 | K5: =ROUND(J5*Balance!$B$9,0) -> 6 | L5: =ROUND(J5*Balance!$B$10,0) -> 4 | M5: =J5-K5-L5 -> 2 | N5: Precise, segment-targeted; low gaffe. | O5: M02 | P5: Canon: Lore Databook, October_2018_Politicians (cols B–G)
A6: OP05 | B6: Shizutake Matsumae | C6: Country Initiative | D6: Construction and Development | E6: Nationalist | F6: Appeal | G6: Divisive | H6: =IFERROR(INDEX(Suits!$B$2:$B$7,MATCH(F6,Suits!$A$2:$A$7,0)),"?") -> 求心 | I6: =IFERROR(INDEX(Suits!$B$2:$B$7,MATCH(G6,Suits!$A$2:$A$7,0)),"?") -> 分断 | J6: =Balance!$B$8 -> 12 | K6: =ROUND(J6*Balance!$B$9,0) -> 6 | L6: =ROUND(J6*Balance!$B$10,0) -> 4 | M6: =J6-K6-L6 -> 2 | N6: Rallies loyalists, then draws battle lines. | O6: M06 | P6: Canon: Lore Databook, October_2018_Politicians (cols B–G)
A7: OP06 | B7: Mao Saeki | C7: Butsutou | D7: Foreign Affairs | E7: Globalist | F7: Earnest | G7: Data Driven | H7: =IFERROR(INDEX(Suits!$B$2:$B$7,MATCH(F7,Suits!$A$2:$A$7,0)),"?") -> 誠実 | I7: =IFERROR(INDEX(Suits!$B$2:$B$7,MATCH(G7,Suits!$A$2:$A$7,0)),"?") -> 実証 | J7: =Balance!$B$8 -> 12 | K7: =ROUND(J7*Balance!$B$9,0) -> 6 | L7: =ROUND(J7*Balance!$B$10,0) -> 4 | M7: =J7-K7-L7 -> 2 | N7: Patient, clean; wins long debates. | O7: M03 | P7: Canon: Lore Databook, October_2018_Politicians (cols B–G)
A8: OP07 | B8: Tobira Hideyoshi | C8: Five Point Independents | D8: Ethics and Prosecution | E8: Liberal | F8: Duplicitous | G8: Divisive | H8: =IFERROR(INDEX(Suits!$B$2:$B$7,MATCH(F8,Suits!$A$2:$A$7,0)),"?") -> 二枚舌 | I8: =IFERROR(INDEX(Suits!$B$2:$B$7,MATCH(G8,Suits!$A$2:$A$7,0)),"?") -> 分断 | J8: =Balance!$B$8 -> 12 | K8: =ROUND(J8*Balance!$B$9,0) -> 6 | L8: =ROUND(J8*Balance!$B$10,0) -> 4 | M8: =J8-K8-L8 -> 2 | N8: High-variance trickster. | O8: M07 | P8: Canon: Lore Databook, October_2018_Politicians (cols B–G)
A9: OP08 | B9: Aki Rono | C9: Yezo Heritage Party | D9: Prime Minister | E9: Identity | F9: Earnest | G9: Emotional | H9: =IFERROR(INDEX(Suits!$B$2:$B$7,MATCH(F9,Suits!$A$2:$A$7,0)),"?") -> 誠実 | I9: =IFERROR(INDEX(Suits!$B$2:$B$7,MATCH(G9,Suits!$A$2:$A$7,0)),"?") -> 情熱 | J9: =Balance!$B$8 -> 12 | K9: =ROUND(J9*Balance!$B$9,0) -> 6 | L9: =ROUND(J9*Balance!$B$10,0) -> 4 | M9: =J9-K9-L9 -> 2 | N9: Boss: sincere resilience plus passionate bursts. | O9: M01, M04 | P9: Canon: Lore Databook, October_2018_Politicians (cols B–G)
A10: OP09 | B10: Walter Peard | C10: Keizaijiyuutou | D10: Environment | E10: Ecologist | F10: Emotional | G10: Duplicitous | H10: =IFERROR(INDEX(Suits!$B$2:$B$7,MATCH(F10,Suits!$A$2:$A$7,0)),"?") -> 情熱 | I10: =IFERROR(INDEX(Suits!$B$2:$B$7,MATCH(G10,Suits!$A$2:$A$7,0)),"?") -> 二枚舌 | J10: =Balance!$B$8 -> 12 | K10: =ROUND(J10*Balance!$B$9,0) -> 6 | L10: =ROUND(J10*Balance!$B$10,0) -> 4 | M10: =J10-K10-L10 -> 2 | N10: Committee chair: emotional pressure on undecided members, evasive guards. | O10: M02 | P10: Canon: Lore Databook, October_2018_Politicians (cols B–G)

Sheet Yoron
A1: Topic ID | B1: Topic (databook dimension) | C1: Topic (JP) | D1: Romaji | E1: Start value (0–100) | F1: Note
A2: Y01 | B2: Taxation | C2: 税制 | D2: Zeisei | E2: 50 | F2: Placeholder. Value = public support for MORE of this topic. Seeding decision pending (README #3).
A3: Y02 | B3: Federal Spending | C3: 財政支出 | D3: Zaisei Shishutsu | E3: 50 | F3: Placeholder. Value = public support for MORE of this topic. Seeding decision pending (README #3).
A4: Y03 | B4: Environmentalism | C4: 環境 | D4: Kankyō | E4: 50 | F4: Placeholder. Value = public support for MORE of this topic. Seeding decision pending (README #3).
A5: Y04 | B5: Ainu Enhancement | C5: アイヌ施策 | D5: Ainu Shisaku | E5: 50 | F5: Placeholder. Value = public support for MORE of this topic. Seeding decision pending (README #3).
A6: Y05 | B6: Immigration | C6: 移民 | D6: Imin | E6: 50 | F6: Placeholder. Value = public support for MORE of this topic. Seeding decision pending (README #3).
A7: Y06 | B7: Militarism | C7: 防衛 | D7: Bōei | E7: 50 | F7: Placeholder. Value = public support for MORE of this topic. Seeding decision pending (README #3).
A8: Y07 | B8: Regulation | C8: 規制 | D8: Kisei | E8: 50 | F8: Placeholder. Value = public support for MORE of this topic. Seeding decision pending (README #3).
A9: Y08 | B9: Rural Focus | C9: 農村振興 | D9: Nōson Shinkō | E9: 50 | F9: Placeholder. Value = public support for MORE of this topic. Seeding decision pending (README #3).

Sheet Bills
A1: Bill ID | B1: Title [placeholder] | C1: Topic ID | D1: Topic | E1: Direction (+1 more / −1 less) | F1: Yoron value | G1: Alignment | H1: Difficulty mod (opp start +) | I1: Note
A2: B01 | B2: Example: Coastal Resilience Act | C2: Y03 | D2: =IFERROR(INDEX(Yoron!$B$2:$B$9,MATCH(C2,Yoron!$A$2:$A$9,0)),"?") -> Environmentalism | E2: 1 | F2: =IFERROR(INDEX(Yoron!$E$2:$E$9,MATCH(C2,Yoron!$A$2:$A$9,0)),"") -> 50 | G2: =IF(E2=1,F2,100-F2) -> 50 | H2: =ROUND((Balance!$B$17-G2)*Balance!$B$16,0) -> 0 | I2: Titles are illustrative only — replace with canon bills.
A3: B02 | B3: Example: Consumption Tax Reduction | C3: Y01 | D3: =IFERROR(INDEX(Yoron!$B$2:$B$9,MATCH(C3,Yoron!$A$2:$A$9,0)),"?") -> Taxation | E3: -1 | F3: =IFERROR(INDEX(Yoron!$E$2:$E$9,MATCH(C3,Yoron!$A$2:$A$9,0)),"") -> 50 | G3: =IF(E3=1,F3,100-F3) -> 50 | H3: =ROUND((Balance!$B$17-G3)*Balance!$B$16,0) -> 0 | I3: Titles are illustrative only — replace with canon bills.
A4: B03 | B4: Example: Ainu Language Education Act | C4: Y04 | D4: =IFERROR(INDEX(Yoron!$B$2:$B$9,MATCH(C4,Yoron!$A$2:$A$9,0)),"?") -> Ainu Enhancement | E4: 1 | F4: =IFERROR(INDEX(Yoron!$E$2:$E$9,MATCH(C4,Yoron!$A$2:$A$9,0)),"") -> 50 | G4: =IF(E4=1,F4,100-F4) -> 50 | H4: =ROUND((Balance!$B$17-G4)*Balance!$B$16,0) -> 0 | I4: Titles are illustrative only — replace with canon bills.

Sheet Committee
A1: Module | B1: Seq | C1: Member | D1: Party | E1: Positioning | F1: Element 1 | G1: Element 2 | H1: Starting stance [proposed] | I1: Primary suit | J1: Source
A2: MOD01 | B2: 2 | C2: Noah Kain | D2: Frontier Party | E2: Ecologist | F2: Earnest | G2: Data Driven | H2: Undecided | I2: =IFERROR(INDEX(Suits!$B$2:$B$7,MATCH(F2,Suits!$A$2:$A$7,0)),"?") -> 誠実 | J2: Canon: Lore Databook, Environment committee (2018)
A3: MOD01 | B3: 2 | C3: Ran Sachiko | D3: Butsutou | E3: Ecologist | F3: Earnest | G3: Emotional | H3: Undecided | I3: =IFERROR(INDEX(Suits!$B$2:$B$7,MATCH(F3,Suits!$A$2:$A$7,0)),"?") -> 誠実 | J3: Canon: Lore Databook, Environment committee (2018)
A4: MOD01 | B4: 2 | C4: Kotake Kasumu | D4: Butsutou | E4: Ecologist | F4: Appeal | G4: Emotional | H4: Undecided | I4: =IFERROR(INDEX(Suits!$B$2:$B$7,MATCH(F4,Suits!$A$2:$A$7,0)),"?") -> 求心 | J4: Canon: Lore Databook, Environment committee (2018)
A5: MOD01 | B5: 2 | C5: Isoroku Adams | D5: Keizaijiyuutou | E5: Ecologist | F5: Appeal | G5: Divisive | H5: Against | I5: =IFERROR(INDEX(Suits!$B$2:$B$7,MATCH(F5,Suits!$A$2:$A$7,0)),"?") -> 求心 | J5: Canon: Lore Databook, Environment committee (2018)

Sheet Modules
A1: Module | B1: Seq | C1: Stage ID | D1: Stage | E1: Mode | F1: Opp ID | G1: Opponent | H1: Bill ID | I1: Opp start support | J1: Win threshold | K1: XP reward | L1: Note | M1: Difficulty | N1: Committee size | O1: Size in band?
A2: MOD01 | B2: 1 | C2: ST07 | D2: =IFERROR(INDEX(Stages!$B$2:$B$9,MATCH(C2,Stages!$A$2:$A$9,0)),"?") -> Office Hours | E2: =IFERROR(INDEX(Stages!$E$2:$E$9,MATCH(C2,Stages!$A$2:$A$9,0)),"?") -> Non-combat | G2: =IF(F2="","—",IFERROR(INDEX(Opponents!$B$2:$B$10,MATCH(F2,Opponents!$A$2:$A$10,0)),"?")) -> — | H2: B01 | I2: =IF(E2<>"Combat","—",IF(C2="ST01",ROUND(N2*Balance!$B$23,0),INDEX(Stages!$O$2:$O$9,MATCH(C2,Stages!$A$2:$A$9,0))+IFERROR(INDEX(Bills!$H$2:$H$4,MATCH(H2,Bills!$A$2:$A$4,0)),0))) -> — | J2: =IF(E2<>"Combat","—",IF(C2="ST01",INT(N2/2)+1,INDEX(Stages!$H$2:$H$9,MATCH(C2,Stages!$A$2:$A$9,0)))) -> — | K2: =INDEX(Stages!$Z$2:$Z$9,MATCH(C2,Stages!$A$2:$A$9,0)) -> 10 | L2: Pre-module office hours: sets Jiban/Kaban going in. | O2: =IF(C2<>"ST01","",IF(AND(N2>=INDEX(Balance!$B$20:$B$22,MATCH(M2,Balance!$A$20:$A$22,0)),N2<=INDEX(Balance!$C$20:$C$22,MATCH(M2,Balance!$A$20:$A$22,0))),"ok","OUT OF BAND"))
A3: MOD01 | B3: 2 | C3: ST01 | D3: =IFERROR(INDEX(Stages!$B$2:$B$9,MATCH(C3,Stages!$A$2:$A$9,0)),"?") -> Committee | E3: =IFERROR(INDEX(Stages!$E$2:$E$9,MATCH(C3,Stages!$A$2:$A$9,0)),"?") -> Combat | F3: OP09 | G3: =IF(F3="","—",IFERROR(INDEX(Opponents!$B$2:$B$10,MATCH(F3,Opponents!$A$2:$A$10,0)),"?")) -> Walter Peard | H3: B01 | I3: =IF(E3<>"Combat","—",IF(N3>0,COUNTIFS(Committee!$A$2:$A$100,A3,Committee!$B$2:$B$100,B3,Committee!$H$2:$H$100,"Against"),ROUND(N3*Balance!$B$23,0))) -> 1 | J3: =IF(E3<>"Combat","—",IF(C3="ST01",INT(N3/2)+1,INDEX(Stages!$H$2:$H$9,MATCH(C3,Stages!$A$2:$A$9,0)))) -> 3 | K3: =INDEX(Stages!$Z$2:$Z$9,MATCH(C3,Stages!$A$2:$A$9,0)) -> 20 | L3: Environment committee review of B01. Chair: Walter Peard (canon Environment member). Members listed in Committee tab. | M3: Easy | N3: =COUNTIFS(Committee!$A$2:$A$100,A3,Committee!$B$2:$B$100,B3) -> 4 | O3: =IF(C3<>"ST01","",IF(AND(N3>=INDEX(Balance!$B$20:$B$22,MATCH(M3,Balance!$A$20:$A$22,0)),N3<=INDEX(Balance!$C$20:$C$22,MATCH(M3,Balance!$A$20:$A$22,0))),"ok","OUT OF BAND")) -> ok
A4: MOD01 | B4: 3 | C4: ST03 | D4: =IFERROR(INDEX(Stages!$B$2:$B$9,MATCH(C4,Stages!$A$2:$A$9,0)),"?") -> Party Caucus | E4: =IFERROR(INDEX(Stages!$E$2:$E$9,MATCH(C4,Stages!$A$2:$A$9,0)),"?") -> Combat | F4: OP02 | G4: =IF(F4="","—",IFERROR(INDEX(Opponents!$B$2:$B$10,MATCH(F4,Opponents!$A$2:$A$10,0)),"?")) -> Yuriko Mayeda | H4: B01 | I4: =IF(E4<>"Combat","—",IF(C4="ST01",ROUND(N4*Balance!$B$23,0),INDEX(Stages!$O$2:$O$9,MATCH(C4,Stages!$A$2:$A$9,0))+IFERROR(INDEX(Bills!$H$2:$H$4,MATCH(H4,Bills!$A$2:$A$4,0)),0))) -> 40 | J4: =IF(E4<>"Combat","—",IF(C4="ST01",INT(N4/2)+1,INDEX(Stages!$H$2:$H$9,MATCH(C4,Stages!$A$2:$A$9,0)))) -> 60 | K4: =INDEX(Stages!$Z$2:$Z$9,MATCH(C4,Stages!$A$2:$A$9,0)) -> 25 | L4: Caucus rival — replace with same-party opponent once protagonist's party is set (README #2). | O4: =IF(C4<>"ST01","",IF(AND(N4>=INDEX(Balance!$B$20:$B$22,MATCH(M4,Balance!$A$20:$A$22,0)),N4<=INDEX(Balance!$C$20:$C$22,MATCH(M4,Balance!$A$20:$A$22,0))),"ok","OUT OF BAND"))
A5: MOD01 | B5: 4 | C5: ST02 | D5: =IFERROR(INDEX(Stages!$B$2:$B$9,MATCH(C5,Stages!$A$2:$A$9,0)),"?") -> Floor Debate | E5: =IFERROR(INDEX(Stages!$E$2:$E$9,MATCH(C5,Stages!$A$2:$A$9,0)),"?") -> Combat | F5: OP03 | G5: =IF(F5="","—",IFERROR(INDEX(Opponents!$B$2:$B$10,MATCH(F5,Opponents!$A$2:$A$10,0)),"?")) -> Masato Maruyama | H5: B01 | I5: =IF(E5<>"Combat","—",IF(C5="ST01",ROUND(N5*Balance!$B$23,0),INDEX(Stages!$O$2:$O$9,MATCH(C5,Stages!$A$2:$A$9,0))+IFERROR(INDEX(Bills!$H$2:$H$4,MATCH(H5,Bills!$A$2:$A$4,0)),0))) -> 40 | J5: =IF(E5<>"Combat","—",IF(C5="ST01",INT(N5/2)+1,INDEX(Stages!$H$2:$H$9,MATCH(C5,Stages!$A$2:$A$9,0)))) -> 51 | K5: =INDEX(Stages!$Z$2:$Z$9,MATCH(C5,Stages!$A$2:$A$9,0)) -> 40 | L5: Floor vote: 51 of 101 seats. | O5: =IF(C5<>"ST01","",IF(AND(N5>=INDEX(Balance!$B$20:$B$22,MATCH(M5,Balance!$A$20:$A$22,0)),N5<=INDEX(Balance!$C$20:$C$22,MATCH(M5,Balance!$A$20:$A$22,0))),"ok","OUT OF BAND"))
J6: Module XP | K6: =SUM(K2:K5) -> 95

Sheet Sanban
A1: Variable | B1: JP | C1: Romaji | D1: Start | E1: Min | F1: Max | G1: Low threshold | H1: Low consequence | I1: High threshold | J1: High consequence | K1: Fed by | L1: Critical threshold | M1: Critical consequence
A2: Constituency support | B2: 地盤 | C2: Jiban | D2: 50 | E2: 0 | F2: 100 | G2: =Balance!$B$25 -> 15 | H2: Triggers Town Hall event (ST05); winning it restores Jiban. | I2: 80 | J2: Election victory; party post eligibility (titles TBD) | K2: Office hours, Town Hall wins | L2: =Balance!$B$26 -> 0 | M2: All funding frozen (Kaban income = 0) until Jiban rises above 0.
A3: Reputation | B3: 看板 | C3: Kanban | D3: 50 | E3: 0 | F3: 100 | G3: 20 | H3: Press stages start at −5 support | I3: 80 | J3: Press stages start at +5 support | K3: Press Conference, TV Debate
A4: Funds | B4: 鞄 | C4: Kaban | D4: 30 | E4: 0 | F4: 999 | G4: 0 | H4: Cannot buy modifiers or hire staff | I4: 100 | J4: Unlock premium modifiers | K4: Donor visits, M02
A5: Party support | B5: 党内支持 | C5: Tōnai Shiji | D5: 50 | E5: 0 | F5: 100 | G5: =Balance!$B$28 -> 50 | H5: Debuff M10 (Cold Shoulder) active | I5: =Balance!$B$27 -> 75 | J5: Allied buff M09 (Party Backing) active | K5: Caucus results (Stages col AB), party-line votes | L5: =Balance!$B$29 -> 25 | M5: Party Steering Committee stage (ST08) triggered

Sheet Lists
A1: Suits | B1: Types | C1: Segments | D1: Tiers | E1: Modes | F1: ModCategory | G1: Difficulty | H1: Tier | I1: Status | J1: Stance | K1: AssetSource
A2: Earnest | B2: Gain | C2: Any | D2: Starter | E2: Combat | F2: Kōenkai | G2: Easy | H2: Party | I2: Not started | J2: For | K2: ComiPo!
A3: Emotional | B3: Attack | C3: Press | D3: Tier 1 | E3: Non-combat | F3: Bankisha | G3: Normal | H3: Constituency | I3: Rendered | J3: Undecided | K3: Midjourney
A4: Appeal | B4: Defend | C4: Loyalists | D4: Tier 2 | F4: Dantai | G4: Hard | H4: National | I4: Edited | J4: Against | K4: ComiPo! + Midjourney
A5: Data Driven | B5: Buff | C5: Constituents | F5: Debuff | I5: In engine | K5: Manual
A6: Divisive | B6: Utility | C6: Donors | F6: Party | K6: Engine/UI
A7: Duplicitous | C7: Bureaucrats | F7: Local | K7: Library
K8: Writing
K9: Export

Sheet Assets
A1: Asset ID | B1: Category | C1: Asset | D1: Detail | E1: Linked ID | F1: Full count | G1: Module 01 count | H1: Source | I1: Status | J1: Notes | L1: Category | M1: Full count | N1: Module 01 | O1: In engine | P1: % done
A2: CH01 | B2: Characters | C2: Protagonist | D2: Bust portrait: neutral, confident, attacking, flustered, victory, defeat | E2: — | F2: 6 | G2: 6 | H2: ComiPo! + Midjourney | I2: Not started | J2: Build all from one base pose | L2: Characters | M2: =SUMIF($B$2:$B$101,L2,$F$2:$F$101) -> 74 | N2: =SUMIF($B$2:$B$101,L2,$G$2:$G$101) -> 31 | O2: =SUMIFS($F$2:$F$101,$B$2:$B$101,L2,$I$2:$I$101,"In engine") -> 0 | P2: =IF(M2=0,"",O2/M2) -> 0
A3: CH02 | B3: Characters | C3: =Opponents!B2 -> Barclay Brigham | D3: 5 expressions: neutral, attacking, confident, flustered, defeated | E3: OP01 | F3: 5 | G3: 0 | H3: ComiPo! + Midjourney | I3: Not started | L3: Cards | M3: =SUMIF($B$2:$B$101,L3,$F$2:$F$101) -> 35 | N3: =SUMIF($B$2:$B$101,L3,$G$2:$G$101) -> 22 | O3: =SUMIFS($F$2:$F$101,$B$2:$B$101,L3,$I$2:$I$101,"In engine") -> 0 | P3: =IF(M3=0,"",O3/M3) -> 0
A4: CH03 | B4: Characters | C4: =Opponents!B3 -> Yuriko Mayeda | D4: 5 expressions: neutral, attacking, confident, flustered, defeated | E4: OP02 | F4: 5 | G4: 5 | H4: ComiPo! + Midjourney | I4: Not started | L4: Backgrounds | M4: =SUMIF($B$2:$B$101,L4,$F$2:$F$101) -> 8 | N4: =SUMIF($B$2:$B$101,L4,$G$2:$G$101) -> 4 | O4: =SUMIFS($F$2:$F$101,$B$2:$B$101,L4,$I$2:$I$101,"In engine") -> 0 | P4: =IF(M4=0,"",O4/M4) -> 0
A5: CH04 | B5: Characters | C5: =Opponents!B4 -> Masato Maruyama | D5: 5 expressions: neutral, attacking, confident, flustered, defeated | E5: OP03 | F5: 5 | G5: 5 | H5: ComiPo! + Midjourney | I5: Not started | L5: Icons | M5: =SUMIF($B$2:$B$101,L5,$F$2:$F$101) -> 53 | N5: =SUMIF($B$2:$B$101,L5,$G$2:$G$101) -> 38 | O5: =SUMIFS($F$2:$F$101,$B$2:$B$101,L5,$I$2:$I$101,"In engine") -> 0 | P5: =IF(M5=0,"",O5/M5) -> 0
A6: CH05 | B6: Characters | C6: =Opponents!B5 -> Kitahime Haibi | D6: 5 expressions: neutral, attacking, confident, flustered, defeated | E6: OP04 | F6: 5 | G6: 0 | H6: ComiPo! + Midjourney | I6: Not started | L6: Screens | M6: =SUMIF($B$2:$B$101,L6,$F$2:$F$101) -> 14 | N6: =SUMIF($B$2:$B$101,L6,$G$2:$G$101) -> 12 | O6: =SUMIFS($F$2:$F$101,$B$2:$B$101,L6,$I$2:$I$101,"In engine") -> 0 | P6: =IF(M6=0,"",O6/M6) -> 0
A7: CH06 | B7: Characters | C7: =Opponents!B6 -> Shizutake Matsumae | D7: 5 expressions: neutral, attacking, confident, flustered, defeated | E7: OP05 | F7: 5 | G7: 0 | H7: ComiPo! + Midjourney | I7: Not started | L7: Branding | M7: =SUMIF($B$2:$B$101,L7,$F$2:$F$101) -> 11 | N7: =SUMIF($B$2:$B$101,L7,$G$2:$G$101) -> 2 | O7: =SUMIFS($F$2:$F$101,$B$2:$B$101,L7,$I$2:$I$101,"In engine") -> 0 | P7: =IF(M7=0,"",O7/M7) -> 0
A8: CH07 | B8: Characters | C8: =Opponents!B7 -> Mao Saeki | D8: 5 expressions: neutral, attacking, confident, flustered, defeated | E8: OP06 | F8: 5 | G8: 0 | H8: ComiPo! + Midjourney | I8: Not started | L8: Audio | M8: =SUMIF($B$2:$B$101,L8,$F$2:$F$101) -> 26 | N8: =SUMIF($B$2:$B$101,L8,$G$2:$G$101) -> 14 | O8: =SUMIFS($F$2:$F$101,$B$2:$B$101,L8,$I$2:$I$101,"In engine") -> 0 | P8: =IF(M8=0,"",O8/M8) -> 0
A9: CH08 | B9: Characters | C9: =Opponents!B8 -> Tobira Hideyoshi | D9: 5 expressions: neutral, attacking, confident, flustered, defeated | E9: OP07 | F9: 5 | G9: 0 | H9: ComiPo! + Midjourney | I9: Not started | L9: Text | M9: =SUMIF($B$2:$B$101,L9,$F$2:$F$101) -> 186 | N9: =SUMIF($B$2:$B$101,L9,$G$2:$G$101) -> 73 | O9: =SUMIFS($F$2:$F$101,$B$2:$B$101,L9,$I$2:$I$101,"In engine") -> 0 | P9: =IF(M9=0,"",O9/M9) -> 0
