Workbook

Sheet README
A1: Coliseum of Parliament — Starter Card & Stage Data
A2: Purpose | B2: Source-of-truth data for the rhetoric card battler (Godot). Each tab is one data table the engine reads. IDs are the join keys across tabs (see the ID-prefix list below) — keep IDs stable, rename display text freely.
A3: Status | B3: MASTER (v9.22.26 lineage), refreshed 2026-10-13 (Batches 1-3 adopted: bills BI31-BI50, 69 topic rooms ST32-ST100, levels LV63-LV82; Batch 1: eight topic rooms ST24-ST31, levels LV61-LV62, transitions switched on). Every Combat stage has at least one opponent; ST07 (Office Hours) and ST22 (Party Steering Committee Check-In) are Non-combat and ST23 (National Assembly Floor Voting) is a Vote. Fields not yet final are marked as drafts in their own Note/Why cells; the header of every column carries a note saying what it means and what blank does.
A5: TAB GUIDE
A6: Balance | B6: Global tuning levers (starting deck recipe, XP/Yen scaling, question multipliers, vote influence, party opinion weights). 24 levers.
A7: Suits | B7: The 6 canonical rhetorical Elements/suits (Earnest, Emotional, Appeal, Data Driven, Divisive, Duplicitous) with EN (join key) and JP display names. Referenced by Cards, Opponents, Flavor Text, Affinity and the 5 Question tabs.
A8: Stages | B8: 259 stages (ST01–ST259): 225 Combat, 33 Non-combat (Office Hours rooms and ST22 Party Steering Committee Check-In) and 1 Vote (ST23 Floor Voting). ST24 onward are bill-specific copies of a generic stage; each takes its Background ID (a Stages column) from its generic stage unless it has a picture of its own. Per-stage combat stats, audience-segment mix, favored suit (formula, reads Affinity), sequence mode, and win/loss deltas to Jiban/Yen/Reputation/XP/Party support.
A9: Levels | B9: 82 levels (LV01–LV82): LV01–LV30 are the ordinary levels, LV31–LV60 are one-time Floor Vote levels built around bills BI01–BI30, LV61–LV62 are topic levels (rail fares, fishing quotas) with no bill. Sequences 1–10 stage slots (an STxx, or a BIxx for a Floor Vote), XP unlock cost by Policy Research Assistant tier, bonus win-reward ranges, and per-level Win Δ for each organization.
A10: Affinity | B10: Suit × Stage power-multiplier grid; feeds each Stage's 'Favored suit' formula.
A11: Cards | B11: 54 cards (Card ID C01–C54), 9 per suit. Core stats (Cost/Self+/Opp−/Guard/Draw/Gaffe) plus a Special/Special value/Special note trio encoding conditional effects (see the Claude Code data guide for the dispatch keys).
A12: Segments | B12: 5 audience segments (Press, Party Members, Constituents, Donors, Bureaucrats/Other) with starting favorability; Stages mix these, Cards target them.
A13: Modifiers | B13: 45 modifiers (M01–M48, with gaps where some were retired), one or more per organization. Effect is the human-readable description; Effect Type/Target/Value are the machine-readable columns the game reads instead of parsing the prose.
A14: Boosters | B14: 32 booster/organization groups (BO01–BO32) across Party/Constituency/National tiers, each with a comma-separated Linked modifiers list pointing into Modifiers and an optional Starting Standing. Party-tier bodies also carry a Party Lean Multiplier. The Standing Links tab makes one organization follow, or rival, another organization or a meta value.
A15: Shop | B15: 20 shop items (SH01–SH20): XP-cost, Yen-cost and up to two free-text Bonus Condition fields (staff-tier discounts, stacking buffs, etc.).
A16: Staff | B16: 21 hireable staff rows (SF01–SF21) across 3 roles (Policy Research Assistant, Media Spokesperson, District Representative) × starting/upgrade tier combinations, each with free-text Tier 0/1/2 Reward strings in a '+N for <ID>' pattern.
A17: Opponents | B17: 125 opponents (OP01–OP125, journalists included): Title/Gender/Party/Affiliation, up to 3 ranked suits, and Intent Pattern Range for Attack/Gain/Block (range-string battle AI, '0' = never uses that move). Stage is a semicolon-separated list; most opponents fight in several stages.
... A27: Question Themes | B27: 272 question themes, each linked to the organization(s) a Strong answer pleases (Organization, semicolon list) and, optionally, those it sets back (Annoys).
A29: COLOR KEY
A30: Blue text | B30: Hardcoded input — edit freely.
A31: Black text | B31: Formula — do not overwrite.
A32: Green text | B32: Direct link to another tab.
A33: Yellow fill | B33: Open design decision — needs your call.
A35: KNOWN GAPS / OPEN ITEMS
A36: Repeated suits | B36: 19 opponents list the same suit more than once in Suit 1–3. Left as is on purpose: it simply weights that suit.
A37: Unused question ID | B37: Lobbyist Questions has no L63 (IDs run L01–L78). Harmless; the ID is simply unused.
A38: Questions with no Weak grade | B38: About 37 room questions have no W for any suit. The room tabs' footer rules allow it (at least 2 S, at most 2 W), so they are left; a W on each makes the choice of suit matter more.
A39: Newer tabs | B39: Tabs added after this guide (Player Cues, Stage Questions, Party Standing, Law Effects, Vote Influence Triggers/Cues, Level Intro Cues/Thoughts, Transition tabs, How To Play, Office Ticker and others) are described by the notes on their column headers; hover a header cell.

Sheet Balance
A1: Lever | B1: Value | C1: Note
A2: Starter deck size | B2: 15 | C2: Player and default opponent deck size
A3: Jiban: town hall trigger (≤) | B3: 15 | C3: Constituency support at or below this inserts a Town Hall into the level queue.
A4: Party support: funding freeze (≤) | B4: 0 | C4: Party support at or below this freezes Funds income until it rises back above.
A5: Party support: steering committee (<) | B5: 25 | C5: Party support below this inserts the Steering Committee check-in (ST22) into the level queue.
A6: Party support: allied buff (>) | B6: 75 | C6: Party support above this grants M09 (Party Backing) free, on top of anything owned.
A7: Gaffes: lifetime penalty threshold | B7: 50 | C7: Lifetime gaffes at or above this apply the one-time Jiban penalty below.
A8: Gaffes: lifetime penalty jiban delta | B8: -15 | C8: Applied once, the moment lifetime gaffes cross the threshold above.
A9: Vote influence: default threshold | B9: 85 | C9: Floor Vote influence swing (§7.7): how high an enabled trigger variable in the Vote Influence Triggers tab must be to pass the gate.
A10: Vote swing: resistance default | B10: 85 | C10: % of a party's own seats immune to the influence swing by default. A party's own Vote Resistance column (Parties tab) overrides this.
A11: Question: strong multiplier | B11: 1.3 | C11: How much a Strong-graded answer boosts the card's own self_plus/opp_minus this round, on top of stage affinity. Still pleases the asking organization as before.
A12: Question: weak multiplier | B12: 0.7 | C12: How much a Weak-graded answer penalizes the card's own self_plus/opp_minus this round, on top of stage affinity. No tone cost at all any more.
A13: Lean: Party Support Delta | B13: 2 | C13: First-draft Party support ± when the Level Intro screen’s bill-lean choice agrees with or disagrees with your own party’s disposition toward the level’s bill.
... A30: Party salience: Max Factor | B30: 2 | C30: Highest multiplier a high-salience bill can apply to a party's movement.
A31: Text scale: Small | B31: 90 | C31: Text size percent when the player picks Small (Administration menu). Normal is always 100.
A32: Text scale: Large | B32: 120 | C32: Text size percent when the player picks Large.
A33: Transition: Player Thought Chance | B33: 30 | C33: First-draft percent chance (0-100) that a stage transition opens with the player's own private thought (a PLAYER row in Transition Dialogue) before anyone speaks. A transition with nobody to speak always uses a thought if one is written.
A34: Starting Training Session Coupons | B34: 1 | C34: How many Training Session Coupons (SH21, a free Rhetoric Training draw) a new run begins with. 0 = none.
A35: Supermajority: Percent of House | B35: 67 | C35: Share of the whole house (rounded up) a bill flagged Supermajority in Floor Vote Bills' Vote Requirement column needs to pass. 67 is two thirds (68 of 101). First draft; no bill is flagged yet.
A36: Stance: Other Side Please Percent | B36: 50 | C36: First-draft percent (0-100) of a pleasing answer that counts for a bill stakeholder on the side AGAINST your lean (rounded down). 50 means two answers please them as one. Setting back an organization always lands in full.
A37: Stance: Win Drift | B37: 2 | C37: First-draft standing change per won Combat stage in a bill level: the side against your lean loses this much, your own side gains this much. A lost stage moves nothing.
A38: Stance: Vote Delta | B38: 2 | C38: First-draft standing change from your final vote: Aye gives the bill's supporters +this and its opponents -this; Nay the reverse. Abstain moves nothing.
A39: Stance: Flip Abandoned Penalty | B39: 5 | C39: First-draft penalty (instead of the Vote Delta) for the side you leaned with when your final vote contradicts your lean. Switching is never free.
A40: Stance: Flip Recovery Percent | B40: 25 | C40: First-draft percent (0-100, rounded down per organization) of what the stages cost the side you now vote with that you win back by switching. A future backing may raise it.
A41: Stance: Flip Party Support Away | B41: 3 | C41: First-draft Party support lost when you switch your vote to AGAINST your own party's position on the bill.
A42: Stance: Flip Party Support Toward | B42: 1 | C42: First-draft Party support gained when you switch your vote to WITH your own party's position on the bill.
A43: Bill Question Share Percent | B43: 50 | C43: First-draft percent (0-100) of a stage's questions that may come from the bill the level is about (Stage Questions rows with a Bill ID). The rest come from the room's own pools.
A44: Standing Links: Yen Per Point | B44: 10000 | C44: First-draft. How many yen of Funds count as one standing point when Funds drives an organization through the Standing Links tab (Funds is volatile, so this keeps its pull small).
A45: Opponent Cues: General Pool Chance | B45: 25 | C45: First-draft percent (0-100) chance that an opponent's move uses the shared pool for the style they rolled instead of their own personal lines. 0 = personal lines only.
A46: Special Level Delay | B46: 15 | C46: Hours (x3 with the 2026-10-23 calendar; was 5 units). How many hours of the game calendar pass between a crisis trigger (Constituency support at or below its Town Hall threshold, Party support below its Steering Committee threshold) and its special level appearing at the top of the level list. Each stage costs the hours in the Stages tab.
A47: Decay Interval | B47: 0 | C47: 2026-10-23: 0 = decay by hours is off. Standing and meta decay now run once at every week end instead (Week Decay Multiplier below). A positive number still runs decay every that-many hours as well.
... A100: Draft Bill: Cooldown Units | B100: 90 | C100: Hours (x3, 2026-10-23). Game-calendar hours before another bill can be drafted.
A101: Brief: Standard Energy | B101: 3 | C101: Cameron 2026-10-21. Energy per turn the Details panel treats as normal; a room differing from it prints its own number.
A102: Brief: Standard Hand | B102: 5 | C102: Cameron 2026-10-21. Hand size the Details panel treats as normal; a room differing from it prints its own number.
A103: Whip: Base Cost | B103: 10 | C103: Cameron 2026-10-22. Party support spent for each extra vote whipped on a bill vote.
A104: Whip: Against Party Multiplier | B104: 3 | C104: Cameron 2026-10-22. Whip cost is multiplied by this when the player's vote goes against their own party's position on the bill.
A105: Whip: Max Per Vote | B105: 3 | C105: Draft 2026-10-22. Most extra votes that can be whipped on one bill vote.
A106: Whip: Party Support Floor | B106: 30 | C106: Draft 2026-10-22. Stored Party support may never be spent below this, so a whip cannot push the player into the party crisis.
A107: Workday Hours | B107: 8 | C107: Cameron 2026-10-23. Hours in each weekday (Monday to Friday).
A108: Work Days Per Week | B108: 5 | C108: Cameron 2026-10-23. Weekdays in a work week.
...

Sheet Player
A1: player_id | B1: name_en | C1: party | D1: blurb | E1: Constituency support | F1: Reputation | G1: Funds | H1: Party support | I1: starting_xp | J1: Gender | K1: Committee | L1: Positioning | M1: Element 1 | N1: Element 2 | O1: Region | P1: District Name | Q1: District Type
A2: PC01 | B2: Kenshin Sako | C2: Frontier Party | D2: A strong footing to begin with. Easy difficulty. | E2: 35 | F2: 25 | G2: 100000 | H2: 40 | I2: 60 | J2: M | K2: Committee on Ethics and Prosecution | L2: Liberal | M2: Earnest | N2: Emotional | O2: Sōya | P2: Sōya - Wakkanai | Q2: Single Member
A3: PC02 | B3: Haru Yashi | C3: Frontier Party | D3: A steady start. Normal difficulty. | E3: 20 | F3: 15 | G3: 50000 | H3: 10 | I3: 30 | J3: F | K3: Committee on Foreign Affairs | L3: Nationalist | M3: Earnest | N3: Divisive | O3: Iburi | P3: Tomakomai City | Q3: Single Member
A4: PC03 | B4: Arata Ran | C4: Keizaijiyuutou | D4: An uphill climb from day one. Hard difficulty. | E4: 10 | F4: 5 | G4: 25000 | H4: 15 | I4: 0 | J4: F | K4: Committee on Agriculture | L4: Capitalist | M4: Appeal | N4: Emotional | O4: Sapporo | P4: Sapporo Proportional Block 6 | Q4: Proportional Block
A5: PC04 | B5: Jyurou Nishihara | C5: Country Initiative | D5: Already in crisis before your first vote. Very Hard difficulty. | E5: 5 | F5: 0 | G5: 10000 | H5: 0 | I5: 0 | J5: M | K5: Committee on the National Assembly | L5: Traditionalist | M5: Appeal | N5: Duplicitous | O5: Aomori | P5: Aomori Proportional Block 3 | Q5: Proportional Block

Sheet Office Notices
A1: notice_id | B1: slot | C1: condition_type | D1: condition_target | E1: condition_op | F1: condition_value | G1: text_en
A2: ON01 | B2: staff_greeting | C2: staff_role | D2: District Representative | E2: hired | G2: {staff} is greeting visitors.
A3: ON02 | B3: staff_greeting | C3: staff_role | D3: District Representative | E3: not_hired | G3: No one is at the front desk to greet visitors.
A4: ON03 | B4: staff_greeting | C4: staff_role | D4: Policy Research Assistant | E4: hired | G4: {staff} is reviewing committee minutes and reports.
A5: ON04 | B5: staff_greeting | C5: staff_role | D5: Policy Research Assistant | E5: not_hired | G5: No one is reviewing new policy reports.
A6: ON05 | B6: staff_greeting | C6: staff_role | D6: Media Spokesperson | E6: hired | G6: {staff} is answering questions from reporters.
A7: ON06 | B7: staff_greeting | C7: staff_role | D7: Media Spokesperson | E7: not_hired | G7: Calls from the press are going unanswered.
A8: ON07 | B8: press | C8: meta | D8: Reputation | E8: < | F8: 30 | G8: Few visitors are seeking out your office.
A9: ON08 | B9: press | C9: meta | D9: Reputation | E9: >= | F9: 60 | G9: The office is using a waitlist for visitors.
A10: ON09 | B10: press | C10: meta | D10: SG01 | E10: < | F10: 30 | G10: A volunteer student journalist recently visited the office.
A11: ON10 | B11: press | C11: meta | D11: SG01 | E11: >= | F11: 60 | G11: Veteran journalists are visiting the office for a profile piece.
A12: ON11 | B12: press | C12: meta | D12: SG02 | E12: < | F12: 25 | G12: No party colleagues have visited to chat.
A13: ON12 | B13: press | C13: meta | D13: SG02 | E13: >= | F13: 60 | G13: Party members who want to take you to lunch can now use a scheduling system.
A14: ON13 | B14: press | C14: meta | D14: SG03 | E14: < | F14: 10 | G14: Security removed a constituent for shouting obscenities.
A15: ON14 | B15: press | C15: meta | D15: SG03 | E15: < | F15: 25 | G15: A constituent, allegedly, intended to graffiti on your office door.
A16: ON15 | B16: press | C16: meta | D16: SG03 | E16: >= | F16: 60 | G16: An elderly constituent visited and left a gift basket for the office.
A17: ON16 | B17: press | C17: meta | D17: SG03 | E17: >= | F17: 80 | G17: A family from your district visited to take a picture with you.
A18: ON17 | B18: press | C18: meta | D18: SG04 | E18: < | F18: 30 | G18: A former campaign donor left a note demanding the refund of 200,000円.
A19: ON18 | B19: press | C19: meta | D19: SG04 | E19: >= | F19: 70 | G19: A benefactor stopped by the office to deliver a 100,000円 check for use during the next election campaign.
... A21: ON20 | B21: press | C21: meta | D21: SG05 | E21: >= | F21: 80 | G21: Cabinet Legislation Bureau Chief Rika Ashikaga personally delivered the latest bill analysis reports.

Sheet Suits
A1: Element (canon) | B1: Suit (JP) | C1: Romaji | D1: Gloss | E1: Card Design Template
A2: Earnest | B2: 誠実 | C2: Seijitsu | D2: sincerity | E2: Sumo
A3: Emotional | B3: 情熱 | C3: Jōnetsu | D3: passion | E3: Sakura
A4: Appeal | B4: 求心 | C4: Kyūshin | D4: rallying pull | E4: Ukiyoe
A5: Data Driven | B5: 実証 | C5: Jisshō | D5: evidence | E5: Shoji
A6: Divisive | B6: 分断 | C6: Bundan | D6: division | E6: Castle
A7: Duplicitous | B7: 二枚舌 | C7: Nimaijita | D7: two tongues | E7: Ninja

Sheet Stages
A1: Stage ID | B1: Stage (EN) | C1: Stage (JP) | D1: Romaji | E1: Mode | F1: Bar unit | G1: Bar value | H1: Bar max | I1: Win threshold | J1: Win % | K1: Turn limit | L1: 持ち時間 / turn (energy) | M1: Hand size | N1: 失言 gaffe limit | O1: Player start | P1: Opp start | Q1: % Press | R1: % Party Members | S1: % Constituents | T1: % Boosters | U1: % Bureaucrats | V1: % Other | W1: Segment check | X1: Favored suit | Y1: Win ΔJiban | Z1: Win ΔYen | AA1: Win ΔReputation | AB1: Win ΔXP | AC1: Win ΔParty support | AD1: Loss ΔJiban | AE1: Loss ΔYen | AF1: Loss ΔReputation | AG1: Loss ΔXP | AH1: Loss ΔParty support | AI1: Bar Model | AJ1: Energy Mode | AK1: Energy Pool | AL1: Sequence Mode | AM1: Opponent Count | AN1: Question Pool | AO1: Reputation Affects Start | AP1: Reveal In Briefing | AQ1: Loss Ends Level | AR1: Show Transition | AS1: Transition Speaker Count | AT1: Own Party Only | AU1: Threshold Rise Min | AV1: Threshold Rise Max | AW1: Threshold Cap | AX1: Background ID | AY1: Time Units | AZ1: Win ΔDistrict Awareness | BA1: Win ΔNational Awareness
A2: ST01 | B2: Special Committee | C2: 特別委員会 | D2: Tokubetsu Iinkai | E2: Combat | F2: Members | G2: Numerical | H2: 35 | I2: 20 | J2: =IF(AND(ISNUMBER(H2),ISNUMBER(I2)),IF(H2=0,"",I2/H2),"varies") -> 0.57142857 | K2: 7 | L2: 3 | M2: 5 | N2: 5 | O2: 1 | P2: 10 | Q2: 0.1 | R2: 0.4 | S2: 0 | T2: 0 | U2: 0.5 | V2: 0 | W2: =SUM(Q2:V2) -> 1 | X2: =IF(E2<>"Combat","—",IFERROR(INDEX(Affinity!$A$2:$A$7,MATCH(MAX(INDEX(Affinity!$B$2:$V$7,0,MATCH(A2,Affinity!$B$1:$V$1,0))),INDEX(Affinity!$B$2:$V$7,0,MATCH(A2,Affinity!$B$1:$V$1,0)),0)),"—")) -> Earnest | Y2: 0 | Z2: 20000 | AA2: 0 | AB2: 70 | AC2: 0 | AD2: 0 | AE2: 1000 | AF2: 0 | AG2: 1 | AH2: 0 | AI2: Shared_pool | AJ2: per_turn | AL2: reset | AM2: 2 | AO2: No | AR2: Yes | AY2: 4 | BA2: 1
A3: ST02 | B3: Floor Debate | C3: 本会議 | D3: Honkaigi | E3: Combat | F3: Seats | G3: Numerical | H3: 101 | I3: 51 | J3: =IF(AND(ISNUMBER(H3),ISNUMBER(I3)),IF(H3=0,"",I3/H3),"varies") -> 0.5049505 | K3: 10 | L3: 3 | M3: 5 | N3: 4 | O3: 25 | P3: 40 | Q3: 0.2 | R3: 0.35 | S3: 0.05 | T3: 0.15 | U3: 0.15 | V3: 0.1 | W3: =SUM(Q3:V3) -> 1 | X3: =IF(E3<>"Combat","—",IFERROR(INDEX(Affinity!$A$2:$A$7,MATCH(MAX(INDEX(Affinity!$B$2:$V$7,0,MATCH(A3,Affinity!$B$1:$V$1,0))),INDEX(Affinity!$B$2:$V$7,0,MATCH(A3,Affinity!$B$1:$V$1,0)),0)),"—")) -> Appeal | Y3: 0 | Z3: 30000 | AA3: 0 | AB3: 80 | AC3: 0 | AD3: 0 | AE3: 0 | AF3: 0 | AG3: 5 | AH3: 0 | AI3: Shared_pool | AJ3: per_turn | AL3: continuous | AM3: 2 | AO3: No | AR3: Yes | AY3: 4 | BA3: 1
A4: ST03 | B4: Party Caucus | C4: 議員総会 | D4: Giin Sōkai | E4: Combat | F4: Support | G4: Percentage | H4: 100 | I4: 49 | J4: =IF(AND(ISNUMBER(H4),ISNUMBER(I4)),IF(H4=0,"",I4/H4),"varies") -> 0.49 | K4: 10 | L4: 3 | M4: 5 | N4: 5 | O4: 20 | P4: 40 | Q4: 0 | R4: 0.55 | S4: 0 | T4: 0 | U4: 0 | V4: 0.45 | W4: =SUM(Q4:V4) -> 1 | X4: =IF(E4<>"Combat","—",IFERROR(INDEX(Affinity!$A$2:$A$7,MATCH(MAX(INDEX(Affinity!$B$2:$V$7,0,MATCH(A4,Affinity!$B$1:$V$1,0))),INDEX(Affinity!$B$2:$V$7,0,MATCH(A4,Affinity!$B$1:$V$1,0)),0)),"—")) -> Divisive | Y4: 0 | Z4: 20000 | AA4: 1 | AB4: 90 | AC4: 2 | AD4: 0 | AE4: 0 | AF4: -1 | AG4: 1 | AH4: -2 | AI4: Shared_pool | AJ4: per_turn | AL4: continuous | AM4: 2 | AO4: No | AR4: Yes | AT4: Yes | AY4: 4
A5: ST04 | B5: Press Conference | C5: 記者会見 | D5: Kisha Kaiken | E5: Combat | F5: Press tone | G5: Numerical | H5: 100 | I5: 55 | J5: =IF(AND(ISNUMBER(H5),ISNUMBER(I5)),IF(H5=0,"",I5/H5),"varies") -> 0.55 | K5: 6 | L5: 3 | M5: 5 | N5: 4 | O5: 20 | P5: 45 | Q5: 0.9 | R5: 0 | S5: 0 | T5: 0 | U5: 0.05 | V5: 0.05 | W5: =SUM(Q5:V5) -> 1 | X5: =IF(E5<>"Combat","—",IFERROR(INDEX(Affinity!$A$2:$A$7,MATCH(MAX(INDEX(Affinity!$B$2:$V$7,0,MATCH(A5,Affinity!$B$1:$V$1,0))),INDEX(Affinity!$B$2:$V$7,0,MATCH(A5,Affinity!$B$1:$V$1,0)),0)),"—")) -> Appeal | Y5: 1 | Z5: 30000 | AA5: 1 | AB5: 60 | AC5: 1 | AD5: 0 | AE5: 0 | AF5: -2 | AG5: 5 | AH5: -2 | AI5: Single | AJ5: per_turn | AL5: single | AM5: 1 | AN5: press_conference | AO5: Yes | AQ5: No | AR5: Yes | AY5: 2 | BA5: 2
A6: ST05 | B6: Town Hall | C6: 住民集会 | D6: Jūmin Shūkai | E6: Combat | F6: Appeasement | G6: Percentage | H6: 100 | I6: 53 | J6: =IF(AND(ISNUMBER(H6),ISNUMBER(I6)),IF(H6=0,"",I6/H6),"varies") -> 0.53 | K6: 17 | L6: 3 | M6: 5 | N6: 6 | O6: 15 | P6: 20 | Q6: 0.1 | R6: 0.1 | S6: 0.7 | T6: 0.1 | U6: 0 | V6: 0 | W6: =SUM(Q6:V6) -> 1 | X6: =IF(E6<>"Combat","—",IFERROR(INDEX(Affinity!$A$2:$A$7,MATCH(MAX(INDEX(Affinity!$B$2:$V$7,0,MATCH(A6,Affinity!$B$1:$V$1,0))),INDEX(Affinity!$B$2:$V$7,0,MATCH(A6,Affinity!$B$1:$V$1,0)),0)),"—")) -> Earnest | Y6: 5 | Z6: 45000 | AA6: 1 | AB6: 70 | AC6: 0 | AD6: -5 | AE6: 0 | AF6: -3 | AG6: 10 | AH6: 0 | AI6: Shared_pool | AJ6: per_turn | AL6: stream | AM6: 3 | AN6: town_hall | AO6: No | AR6: Yes | AY6: 2 | AZ6: 2
A7: ST06 | B7: TV Debate | C7: 討論番組 | D7: Tōron Bangumi | E7: Combat | F7: Viewer Interest | G7: Numerical | H7: 100 | I7: 65 | J7: =IF(AND(ISNUMBER(H7),ISNUMBER(I7)),IF(H7=0,"",I7/H7),"varies") -> 0.65 | K7: 5 | L7: 5 | M7: 6 | N7: 5 | O7: 60 | P7: 50 | Q7: 0.8 | R7: 0 | S7: 0.2 | T7: 0 | U7: 0 | V7: 0 | W7: =SUM(Q7:V7) -> 1 | X7: =IF(E7<>"Combat","—",IFERROR(INDEX(Affinity!$A$2:$A$7,MATCH(MAX(INDEX(Affinity!$B$2:$V$7,0,MATCH(A7,Affinity!$B$1:$V$1,0))),INDEX(Affinity!$B$2:$V$7,0,MATCH(A7,Affinity!$B$1:$V$1,0)),0)),"—")) -> Appeal | Y7: 3 | Z7: 40000 | AA7: 2 | AB7: 55 | AC7: 2 | AD7: -1 | AE7: 0 | AF7: -3 | AG7: 0 | AH7: -1 | AI7: Survival | AJ7: per_turn | AL7: single | AM7: 1 | AO7: Yes | AR7: Yes | AU7: 0 | AV7: 3 | AY7: 3 | BA7: 3
A8: ST07 | B8: Office Hours | C8: 陳情 | D8: Chinjō | E8: Non-combat | F8: Time slots | G8: Numerical | H8: 10 | I8: 10 | J8: =IF(AND(ISNUMBER(H8),ISNUMBER(I8)),IF(H8=0,"",I8/H8),"varies") -> 1 | K8: 9 | L8: 5 | M8: 5 | N8: 7 | O8: 0 | P8: 0 | Q8: 0 | R8: 0 | S8: 0.7 | T8: 0.3 | U8: 0 | V8: 0 | W8: =SUM(Q8:V8) -> 1 | X8: =IF(E8<>"Combat","—",IFERROR(INDEX(Affinity!$A$2:$A$7,MATCH(MAX(INDEX(Affinity!$B$2:$V$7,0,MATCH(A8,Affinity!$B$1:$V$1,0))),INDEX(Affinity!$B$2:$V$7,0,MATCH(A8,Affinity!$B$1:$V$1,0)),0)),"—")) -> — | Y8: 5 | Z8: 10000 | AA8: 0 | AB8: 50 | AC8: 0 | AD8: 0 | AE8: 0 | AF8: 0 | AG8: 0 | AH8: 0 | AI8: Shared_pool | AJ8: per_turn | AL8: single | AM8: 5 | AO8: No | AQ8: No | AY8: 2 | AZ8: 1
A9: ST08 | B9: Party Steering Committee | C9: 党運営委員会 | D9: Tō Un'ei Iinkai | E9: Combat | F9: Support | G9: Percentage | H9: 100 | I9: 43 | J9: =IF(AND(ISNUMBER(H9),ISNUMBER(I9)),IF(H9=0,"",I9/H9),"varies") -> 0.43 | K9: 5 | L9: 3 | M9: 5 | N9: 5 | O9: 20 | P9: 50 | Q9: 0 | R9: 0.7 | S9: 0 | T9: 0 | U9: 0 | V9: 0.3 | W9: =SUM(Q9:V9) -> 1 | X9: =IF(E9<>"Combat","—",IFERROR(INDEX(Affinity!$A$2:$A$7,MATCH(MAX(INDEX(Affinity!$B$2:$V$7,0,MATCH(A9,Affinity!$B$1:$V$1,0))),INDEX(Affinity!$B$2:$V$7,0,MATCH(A9,Affinity!$B$1:$V$1,0)),0)),"—")) -> Divisive | Y9: 0 | Z9: 20000 | AA9: 2 | AB9: 90 | AC9: 5 | AD9: 0 | AE9: 0 | AF9: -3 | AG9: 5 | AH9: -5 | AI9: Shared_pool | AJ9: pool | AK9: 8 | AL9: single | AM9: 1 | AO9: No | AR9: Yes | AT9: Yes | AY9: 4 | BA9: 1
A10: ST09 | B10: Committee on Ethics and Prosecution | C10: 倫理起訴委員会 | D10: Rinri Kiso Iinkai | E10: Combat | F10: Favorability | G10: Percentage | H10: 100 | I10: 78 | J10: =IF(AND(ISNUMBER(H10),ISNUMBER(I10)),IF(H10=0,"",I10/H10),"varies") -> 0.78 | K10: 10 | L10: 5 | M10: 5 | N10: 5 | O10: 20 | P10: 30 | Q10: 0.35 | R10: 0.4 | S10: 0 | T10: 0 | U10: 0.1 | V10: 0.15 | W10: =SUM(Q10:V10) -> 1 | X10: =IF(E10<>"Combat","—",IFERROR(INDEX(Affinity!$A$2:$A$7,MATCH(MAX(INDEX(Affinity!$B$2:$V$7,0,MATCH(A10,Affinity!$B$1:$V$1,0))),INDEX(Affinity!$B$2:$V$7,0,MATCH(A10,Affinity!$B$1:$V$1,0)),0)),"—")) -> Emotional | Y10: 2 | Z10: 20000 | AA10: 2 | AB10: 40 | AC10: 2 | AD10: 0 | AE10: 0 | AF10: 0 | AG10: 0 | AH10: 0 | AI10: Shared_pool | AJ10: per_turn | AL10: reset | AM10: 4 | AO10: No | AR10: Yes | AY10: 4 | BA10: 1
A11: ST10 | B11: Committee on the Environment | C11: 環境委員会 | D11: Kankyō Iinkai | E11: Combat | F11: Favorability | G11: Percentage | H11: 100 | I11: 66 | J11: =IF(AND(ISNUMBER(H11),ISNUMBER(I11)),IF(H11=0,"",I11/H11),"varies") -> 0.66 | K11: 10 | L11: 5 | M11: 5 | N11: 7 | O11: 30 | P11: 30 | Q11: 0 | R11: 0.1 | S11: 0.65 | T11: 0 | U11: 0.2 | V11: 0.05 | W11: =SUM(Q11:V11) -> 1 | X11: =IF(E11<>"Combat","—",IFERROR(INDEX(Affinity!$A$2:$A$7,MATCH(MAX(INDEX(Affinity!$B$2:$V$7,0,MATCH(A11,Affinity!$B$1:$V$1,0))),INDEX(Affinity!$B$2:$V$7,0,MATCH(A11,Affinity!$B$1:$V$1,0)),0)),"—")) -> Earnest | Y11: 2 | Z11: 10000 | AA11: 1 | AB11: 40 | AC11: 0 | AD11: -1 | AE11: 1000 | AF11: 0 | AG11: 1 | AH11: 0 | AI11: Shared_pool | AJ11: per_turn | AL11: reset | AM11: 2 | AO11: No | AR11: Yes | AY11: 4 | BA11: 1
A12: ST11 | B12: Committee on War | C12: 戦争委員会 | D12: Sensō Iinkai | E12: Combat | F12: Favorability | G12: Percentage | H12: 100 | I12: 72 | J12: =IF(AND(ISNUMBER(H12),ISNUMBER(I12)),IF(H12=0,"",I12/H12),"varies") -> 0.72 | K12: 10 | L12: 3 | M12: 5 | N12: 5 | O12: 25 | P12: 25 | Q12: 0.55 | R12: 0 | S12: 0.05 | T12: 0.25 | U12: 0.15 | V12: 0 | W12: =SUM(Q12:V12) -> 1 | X12: =IF(E12<>"Combat","—",IFERROR(INDEX(Affinity!$A$2:$A$7,MATCH(MAX(INDEX(Affinity!$B$2:$V$7,0,MATCH(A12,Affinity!$B$1:$V$1,0))),INDEX(Affinity!$B$2:$V$7,0,MATCH(A12,Affinity!$B$1:$V$1,0)),0)),"—")) -> Divisive | Y12: 0 | Z12: 10000 | AA12: 1 | AB12: 20 | AC12: 2 | AD12: 0 | AE12: 0 | AF12: 0 | AG12: 1 | AH12: 0 | AI12: Shared_pool | AJ12: per_turn | AL12: reset | AM12: 2 | AO12: No | AR12: Yes | AY12: 4 | BA12: 1
A13: ST12 | B13: Committee on the National Assembly | C13: 国会管理委員会 | D13: Kokkai Kanri Iinkai | E13: Combat | F13: Favorability | G13: Percentage | H13: 100 | I13: 90 | J13: =IF(AND(ISNUMBER(H13),ISNUMBER(I13)),IF(H13=0,"",I13/H13),"varies") -> 0.9 | K13: 10 | L13: 4 | M13: 5 | N13: 7 | O13: 35 | P13: 30 | Q13: 0 | R13: 0.5 | S13: 0 | T13: 0 | U13: 0.5 | V13: 0 | W13: =SUM(Q13:V13) -> 1 | X13: =IF(E13<>"Combat","—",IFERROR(INDEX(Affinity!$A$2:$A$7,MATCH(MAX(INDEX(Affinity!$B$2:$V$7,0,MATCH(A13,Affinity!$B$1:$V$1,0))),INDEX(Affinity!$B$2:$V$7,0,MATCH(A13,Affinity!$B$1:$V$1,0)),0)),"—")) -> Data Driven | Y13: 0 | Z13: 10000 | AA13: 1 | AB13: 15 | AC13: 3 | AD13: 0 | AE13: 0 | AF13: 0 | AG13: 1 | AH13: 0 | AI13: Shared_pool | AJ13: per_turn | AL13: reset | AM13: 3 | AO13: No | AR13: Yes | AY13: 4 | BA13: 1
A14: ST13 | B14: Committee on Agriculture | C14: 農林水産委員会 | D14: Nōrin Suisan Iinkai | E14: Combat | F14: Favorability | G14: Percentage | H14: 100 | I14: 66 | J14: =IF(AND(ISNUMBER(H14),ISNUMBER(I14)),IF(H14=0,"",I14/H14),"varies") -> 0.66 | K14: 10 | L14: 5 | M14: 5 | N14: 7 | O14: 30 | P14: 30 | Q14: 0 | R14: 0.2 | S14: 0.6 | T14: 0 | U14: 0 | V14: 0.2 | W14: =SUM(Q14:V14) -> 1 | X14: =IF(E14<>"Combat","—",IFERROR(INDEX(Affinity!$A$2:$A$7,MATCH(MAX(INDEX(Affinity!$B$2:$V$7,0,MATCH(A14,Affinity!$B$1:$V$1,0))),INDEX(Affinity!$B$2:$V$7,0,MATCH(A14,Affinity!$B$1:$V$1,0)),0)),"—")) -> Emotional | Y14: 1 | Z14: 10000 | AA14: 1 | AB14: 40 | AC14: 0 | AD14: -1 | AE14: 1000 | AF14: 0 | AG14: 1 | AH14: 0 | AI14: Shared_pool | AJ14: per_turn | AL14: reset | AM14: 2 | AO14: No | AR14: Yes | AY14: 4 | BA14: 1
A15: ST14 | B15: Committee on Foreign Affairs | C15: 外務委員会 | D15: Gaimu Iinkai | E15: Combat | F15: Favorability | G15: Percentage | H15: 100 | I15: 78 | J15: =IF(AND(ISNUMBER(H15),ISNUMBER(I15)),IF(H15=0,"",I15/H15),"varies") -> 0.78 | K15: 10 | L15: 4 | M15: 5 | N15: 5 | O15: 25 | P15: 30 | Q15: 0.4 | R15: 0.2 | S15: 0 | T15: 0.2 | U15: 0.2 | V15: 0 | W15: =SUM(Q15:V15) -> 1 | X15: =IF(E15<>"Combat","—",IFERROR(INDEX(Affinity!$A$2:$A$7,MATCH(MAX(INDEX(Affinity!$B$2:$V$7,0,MATCH(A15,Affinity!$B$1:$V$1,0))),INDEX(Affinity!$B$2:$V$7,0,MATCH(A15,Affinity!$B$1:$V$1,0)),0)),"—")) -> Appeal | Y15: 0 | Z15: 20000 | AA15: 2 | AB15: 40 | AC15: 2 | AD15: 0 | AE15: 0 | AF15: 0 | AG15: 1 | AH15: 0 | AI15: Shared_pool | AJ15: per_turn | AL15: reset | AM15: 3 | AO15: No | AR15: Yes | AY15: 4 | BA15: 1
A16: ST15 | B16: Committee on Construction and Development | C16: 建設成長委員会 | D16: Kensetsu Seichō Iinkai | E16: Combat | F16: Favorability | G16: Percentage | H16: 100 | I16: 72 | J16: =IF(AND(ISNUMBER(H16),ISNUMBER(I16)),IF(H16=0,"",I16/H16),"varies") -> 0.72 | K16: 10 | L16: 3 | M16: 5 | N16: 5 | O16: 30 | P16: 35 | Q16: 0.2 | R16: 0 | S16: 0.2 | T16: 0.2 | U16: 0.2 | V16: 0.2 | W16: =SUM(Q16:V16) -> 1 | X16: =IF(E16<>"Combat","—",IFERROR(INDEX(Affinity!$A$2:$A$7,MATCH(MAX(INDEX(Affinity!$B$2:$V$7,0,MATCH(A16,Affinity!$B$1:$V$1,0))),INDEX(Affinity!$B$2:$V$7,0,MATCH(A16,Affinity!$B$1:$V$1,0)),0)),"—")) -> Duplicitous | Y16: 3 | Z16: 40000 | AA16: 3 | AB16: 75 | AC16: 3 | AD16: -2 | AE16: 0 | AF16: 0 | AG16: 2 | AH16: 0 | AI16: Shared_pool | AJ16: per_turn | AL16: reset | AM16: 2 | AO16: No | AR16: Yes | AY16: 4 | BA16: 1
A17: ST16 | B17: Committee on Finance | C17: 財務委員会 | D17: Zaimu Iinkai | E17: Combat | F17: Favorability | G17: Percentage | H17: 100 | I17: 84 | J17: =IF(AND(ISNUMBER(H17),ISNUMBER(I17)),IF(H17=0,"",I17/H17),"varies") -> 0.84 | K17: 10 | L17: 4 | M17: 5 | N17: 3 | O17: 35 | P17: 40 | Q17: 0.25 | R17: 0 | S17: 0 | T17: 0.35 | U17: 0.4 | V17: 0 | W17: =SUM(Q17:V17) -> 1 | X17: =IF(E17<>"Combat","—",IFERROR(INDEX(Affinity!$A$2:$A$7,MATCH(MAX(INDEX(Affinity!$B$2:$V$7,0,MATCH(A17,Affinity!$B$1:$V$1,0))),INDEX(Affinity!$B$2:$V$7,0,MATCH(A17,Affinity!$B$1:$V$1,0)),0)),"—")) -> Data Driven | Y17: 1 | Z17: 50000 | AA17: 5 | AB17: 75 | AC17: 5 | AD17: 0 | AE17: 0 | AF17: 0 | AG17: 2 | AH17: 0 | AI17: Shared_pool | AJ17: per_turn | AL17: reset | AM17: 3 | AO17: No | AR17: Yes | AY17: 4 | BA17: 1
A18: ST17 | B18: Committee on Government Administration | C18: 政府行政委員会 | D18: Seifu Gyōsei Iinkai | E18: Combat | F18: Favorability | G18: Percentage | H18: 100 | I18: 78 | J18: =IF(AND(ISNUMBER(H18),ISNUMBER(I18)),IF(H18=0,"",I18/H18),"varies") -> 0.78 | K18: 10 | L18: 5 | M18: 5 | N18: 5 | O18: 30 | P18: 40 | Q18: 0.15 | R18: 0 | S18: 0.1 | T18: 0.1 | U18: 0.65 | V18: 0 | W18: =SUM(Q18:V18) -> 1 | X18: =IF(E18<>"Combat","—",IFERROR(INDEX(Affinity!$A$2:$A$7,MATCH(MAX(INDEX(Affinity!$B$2:$V$7,0,MATCH(A18,Affinity!$B$1:$V$1,0))),INDEX(Affinity!$B$2:$V$7,0,MATCH(A18,Affinity!$B$1:$V$1,0)),0)),"—")) -> Data Driven | Y18: 1 | Z18: 50000 | AA18: 5 | AB18: 40 | AC18: 5 | AD18: 0 | AE18: 0 | AF18: 0 | AG18: 2 | AH18: 0 | AI18: Shared_pool | AJ18: per_turn | AL18: reset | AM18: 4 | AO18: No | AR18: Yes | AY18: 4 | BA18: 1
A19: ST18 | B19: Committee of the Cabinet | C19: 内閣員会 | D19: Naikaku Iinkai | E19: Combat | F19: Consensus | G19: Percentage | H19: 100 | I19: 60 | J19: =IF(AND(ISNUMBER(H19),ISNUMBER(I19)),IF(H19=0,"",I19/H19),"varies") -> 0.6 | K19: 10 | L19: 26 | M19: 6 | N19: 3 | O19: 30 | P19: 55 | Q19: 0 | R19: 0.1 | S19: 0 | T19: 0 | U19: 0 | V19: 0.9 | W19: =SUM(Q19:V19) -> 1 | X19: =IF(E19<>"Combat","—",IFERROR(INDEX(Affinity!$A$2:$A$7,MATCH(MAX(INDEX(Affinity!$B$2:$V$7,0,MATCH(A19,Affinity!$B$1:$V$1,0))),INDEX(Affinity!$B$2:$V$7,0,MATCH(A19,Affinity!$B$1:$V$1,0)),0)),"—")) -> Data Driven | Y19: 0 | Z19: 100000 | AA19: 15 | AB19: 120 | AC19: 15 | AD19: 0 | AE19: 0 | AF19: -1 | AG19: 20 | AH19: -10 | AI19: Shared_pool | AJ19: pool | AK19: 26 | AL19: reset | AM19: 2 | AO19: No | AR19: Yes | AY19: 4 | BA19: 1
A20: ST19 | B20: Media Ambush | C20: ぶら下がり取材 | D20: Burasagari Shuzai | E20: Combat | F20: Press tone | G20: Percentage | H20: 50 | I20: 30 | J20: =IF(AND(ISNUMBER(H20),ISNUMBER(I20)),IF(H20=0,"",I20/H20),"varies") -> 0.6 | K20: 11 | L20: 3 | M20: 3 | N20: 2 | O20: 5 | P20: 15 | Q20: 1 | R20: 0 | S20: 0 | T20: 0 | U20: 0 | V20: 0 | W20: =SUM(Q20:V20) -> 1 | X20: =IF(E20<>"Combat","—",IFERROR(INDEX(Affinity!$A$2:$A$7,MATCH(MAX(INDEX(Affinity!$B$2:$V$7,0,MATCH(A20,Affinity!$B$1:$V$1,0))),INDEX(Affinity!$B$2:$V$7,0,MATCH(A20,Affinity!$B$1:$V$1,0)),0)),"—")) -> Emotional | Y20: 2 | Z20: 15000 | AA20: 3 | AB20: 70 | AC20: 1 | AD20: -1 | AE20: 0 | AF20: -1 | AG20: 5 | AH20: -5 | AI20: Shared_pool | AJ20: pool | AK20: 15 | AL20: continuous | AM20: 2 | AN20: media_ambush | AO20: No | AP20: No | AQ20: No | AR20: No | AY20: 1 | BA20: 1
A21: ST20 | B21: Lobbyist Meeting | C21: ロビー活動 | D21: Robī Katsudō | E21: Combat | F21: Appeasement | G21: Percentage | H21: 50 | I21: 25 | J21: =IF(AND(ISNUMBER(H21),ISNUMBER(I21)),IF(H21=0,"",I21/H21),"varies") -> 0.5 | K21: 7 | L21: 3 | M21: 5 | N21: 6 | O21: 5 | P21: 15 | Q21: 0 | R21: 0 | S21: 0 | T21: 1 | U21: 0 | V21: 0 | W21: =SUM(Q21:V21) -> 1 | X21: =IF(E21<>"Combat","—",IFERROR(INDEX(Affinity!$A$2:$A$7,MATCH(MAX(INDEX(Affinity!$B$2:$V$7,0,MATCH(A21,Affinity!$B$1:$V$1,0))),INDEX(Affinity!$B$2:$V$7,0,MATCH(A21,Affinity!$B$1:$V$1,0)),0)),"—")) -> Appeal | Y21: 0 | Z21: 50000 | AA21: 0 | AB21: 75 | AC21: 0 | AD21: 0 | AE21: 0 | AF21: 0 | AG21: 0 | AH21: -1 | AI21: Shared_pool | AJ21: pool | AK21: 12 | AL21: single | AM21: 1 | AN21: lobbyist_meeting | AO21: No | AR21: Yes | AY21: 2
A22: ST21 | B22: Policy Study Session | C22: 政策検討会 | D22: Seisaku Kentōkai | E22: Combat | F22: Consensus | G22: Percentage | H22: 50 | I22: 35 | J22: =IF(AND(ISNUMBER(H22),ISNUMBER(I22)),IF(H22=0,"",I22/H22),"varies") -> 0.7 | K22: 10 | L22: 5 | M22: 5 | N22: 10 | O22: 1 | P22: 10 | Q22: 0 | R22: 0 | S22: 0 | T22: 0 | U22: 0.8 | V22: 0.2 | W22: =SUM(Q22:V22) -> 1 | X22: =IF(E22<>"Combat","—",IFERROR(INDEX(Affinity!$A$2:$A$7,MATCH(MAX(INDEX(Affinity!$B$2:$V$7,0,MATCH(A22,Affinity!$B$1:$V$1,0))),INDEX(Affinity!$B$2:$V$7,0,MATCH(A22,Affinity!$B$1:$V$1,0)),0)),"—")) -> Earnest | Y22: 1 | Z22: 15000 | AA22: 1 | AB22: 55 | AC22: 1 | AD22: 0 | AE22: 0 | AF22: 0 | AG22: 5 | AH22: 0 | AI22: Shared_pool | AJ22: per_turn | AL22: stream | AM22: 2 | AN22: policy_study | AO22: No | AQ22: No | AR22: Yes | AY22: 2
A23: ST22 | B23: Party Steering Committee Check-In | C23: 党運営委員会面談 | D23: Tō Un'ei Iinkai Mendan | E23: Non-combat | F23: Time slots | G23: Numerical | H23: 10 | I23: 10 | J23: 1 | K23: 10 | L23: 5 | M23: 5 | N23: 7 | O23: 0 | P23: 0 | Q23: 0 | R23: 0.7 | S23: 0 | T23: 0.3 | U23: 0 | V23: 0 | W23: 1 | X23: — | Y23: 0 | Z23: 0 | AA23: 0 | AB23: 30 | AC23: 5 | AD23: 0 | AE23: 0 | AF23: 0 | AG23: 0 | AH23: 0 | AI23: Shared_pool | AJ23: per_turn | AL23: single | AM23: 1 | AO23: No | AY23: 2 | BA23: 1
A24: ST23 | B24: National Assembly Floor Voting | C24: 本会議採決 | D24: Honkaigi Saiketsu | E24: Vote | AQ24: No | AY24: 1
A25: ST24 | B25: Town Hall on Commuter Fares | C25: 運賃を巡る住民集会 | D25: Unchin o Meguru Jūmin Shūkai | E25: Combat | F25: Appeasement | G25: Percentage | H25: 100 | I25: 53 | J25: =IF(AND(ISNUMBER(H25),ISNUMBER(I25)),IF(H25=0,"",I25/H25),"varies") -> 0.53 | K25: 17 | L25: 3 | M25: 5 | N25: 6 | O25: 15 | P25: 15 | Q25: 0.1 | R25: 0.1 | S25: 0.6 | T25: 0.1 | U25: 0 | V25: 0.1 | W25: =SUM(Q25:V25) -> 1 | X25: =IF(E25<>"Combat","—",IFERROR(INDEX(Affinity!$A$2:$A$7,MATCH(MAX(INDEX(Affinity!$B$2:$AD$7,0,MATCH(A25,Affinity!$B$1:$AD$1,0))),INDEX(Affinity!$B$2:$AD$7,0,MATCH(A25,Affinity!$B$1:$AD$1,0)),0)),"—")) -> Emotional | Y25: 5 | Z25: 45000 | AA25: 1 | AB25: 70 | AC25: 0 | AD25: -5 | AE25: 0 | AF25: -3 | AG25: 10 | AH25: 0 | AI25: Shared_pool | AJ25: per_turn | AL25: stream | AM25: 3 | AN25: town_hall | AO25: No | AR25: Yes | AX25: ST05 | AY25: 2 | AZ25: 2
A26: ST25 | B26: Policy Study on Rail Timetables | C26: 鉄道ダイヤ政策検討会 | D26: Tetsudō Daiya Seisaku Kentōkai | E26: Combat | F26: Consensus | G26: Percentage | H26: 50 | I26: 43 | J26: =IF(AND(ISNUMBER(H26),ISNUMBER(I26)),IF(H26=0,"",I26/H26),"varies") -> 0.86 | K26: 10 | L26: 5 | M26: 5 | N26: 10 | O26: 2 | P26: 12 | Q26: 0 | R26: 0 | S26: 0.1 | T26: 0 | U26: 0.7 | V26: 0.2 | W26: =SUM(Q26:V26) -> 1 | X26: =IF(E26<>"Combat","—",IFERROR(INDEX(Affinity!$A$2:$A$7,MATCH(MAX(INDEX(Affinity!$B$2:$AD$7,0,MATCH(A26,Affinity!$B$1:$AD$1,0))),INDEX(Affinity!$B$2:$AD$7,0,MATCH(A26,Affinity!$B$1:$AD$1,0)),0)),"—")) -> Data Driven | Y26: 1 | Z26: 15000 | AA26: 1 | AB26: 55 | AC26: 1 | AD26: 0 | AE26: 0 | AF26: 0 | AG26: 5 | AH26: 0 | AI26: Shared_pool | AJ26: per_turn | AL26: stream | AM26: 2 | AN26: policy_study | AO26: No | AQ26: No | AR26: Yes | AX26: ST21 | AY26: 2
A27: ST26 | B27: Press Conference on Raising Train Fares | C27: 運賃改定記者会見 | D27: Unchin Kaitei Kisha Kaiken | E27: Combat | F27: Press tone | G27: Numerical | H27: 100 | I27: 58 | J27: =IF(AND(ISNUMBER(H27),ISNUMBER(I27)),IF(H27=0,"",I27/H27),"varies") -> 0.58 | K27: 6 | L27: 3 | M27: 5 | N27: 4 | O27: 20 | P27: 45 | Q27: 0.85 | R27: 0 | S27: 0.1 | T27: 0 | U27: 0 | V27: 0.05 | W27: =SUM(Q27:V27) -> 1 | X27: =IF(E27<>"Combat","—",IFERROR(INDEX(Affinity!$A$2:$A$7,MATCH(MAX(INDEX(Affinity!$B$2:$AD$7,0,MATCH(A27,Affinity!$B$1:$AD$1,0))),INDEX(Affinity!$B$2:$AD$7,0,MATCH(A27,Affinity!$B$1:$AD$1,0)),0)),"—")) -> Appeal | Y27: 1 | Z27: 30000 | AA27: 1 | AB27: 60 | AC27: 1 | AD27: 0 | AE27: 0 | AF27: -2 | AG27: 5 | AH27: -2 | AI27: Single | AJ27: per_turn | AL27: single | AM27: 1 | AO27: Yes | AQ27: No | AR27: Yes | AX27: ST04 | AY27: 2 | BA27: 2
A28: ST27 | B28: Hearing on Rail Safety | C28: 鉄道安全に関する公聴会 | D28: Tetsudō Anzen ni Kansuru Kōchōkai | E28: Combat | F28: Favorability | G28: Percentage | H28: 100 | I28: 78 | J28: =IF(AND(ISNUMBER(H28),ISNUMBER(I28)),IF(H28=0,"",I28/H28),"varies") -> 0.78 | K28: 10 | L28: 4 | M28: 5 | N28: 6 | O28: 30 | P28: 32 | Q28: 0 | R28: 0.2 | S28: 0.4 | T28: 0 | U28: 0.3 | V28: 0.1 | W28: =SUM(Q28:V28) -> 1 | X28: =IF(E28<>"Combat","—",IFERROR(INDEX(Affinity!$A$2:$A$7,MATCH(MAX(INDEX(Affinity!$B$2:$AD$7,0,MATCH(A28,Affinity!$B$1:$AD$1,0))),INDEX(Affinity!$B$2:$AD$7,0,MATCH(A28,Affinity!$B$1:$AD$1,0)),0)),"—")) -> Data Driven | Y28: 3 | Z28: 20000 | AA28: 3 | AB28: 45 | AC28: 3 | AD28: -2 | AE28: 0 | AF28: 0 | AG28: 2 | AH28: 0 | AI28: Shared_pool | AJ28: per_turn | AL28: reset | AM28: 2 | AO28: No | AR28: Yes | AX28: ST15 | AY28: 4 | BA28: 1
A29: ST28 | B29: Lobbyist Meeting on Fishing Quotas | C29: 漁獲枠に関するロビー活動 | D29: Gyokaku-waku ni Kansuru Robī Katsudō | E29: Combat | F29: Appeasement | G29: Percentage | H29: 50 | I29: 25 | J29: =IF(AND(ISNUMBER(H29),ISNUMBER(I29)),IF(H29=0,"",I29/H29),"varies") -> 0.5 | K29: 7 | L29: 3 | M29: 5 | N29: 6 | O29: 5 | P29: 15 | Q29: 0 | R29: 0 | S29: 0 | T29: 1 | U29: 0 | V29: 0 | W29: =SUM(Q29:V29) -> 1 | X29: =IF(E29<>"Combat","—",IFERROR(INDEX(Affinity!$A$2:$A$7,MATCH(MAX(INDEX(Affinity!$B$2:$AD$7,0,MATCH(A29,Affinity!$B$1:$AD$1,0))),INDEX(Affinity!$B$2:$AD$7,0,MATCH(A29,Affinity!$B$1:$AD$1,0)),0)),"—")) -> Data Driven | Y29: 0 | Z29: 50000 | AA29: 0 | AB29: 75 | AC29: 0 | AD29: 0 | AE29: 0 | AF29: 0 | AG29: 0 | AH29: -1 | AI29: Shared_pool | AJ29: pool | AK29: 12 | AL29: single | AM29: 1 | AN29: lobbyist_meeting | AO29: No | AR29: Yes | AX29: ST20 | AY29: 2
A30: ST29 | B30: Town Hall at the Harbor | C30: 漁港の住民集会 | D30: Gyokō no Jūmin Shūkai | E30: Combat | F30: Appeasement | G30: Percentage | H30: 100 | I30: 53 | J30: =IF(AND(ISNUMBER(H30),ISNUMBER(I30)),IF(H30=0,"",I30/H30),"varies") -> 0.53 | K30: 17 | L30: 3 | M30: 5 | N30: 6 | O30: 15 | P30: 20 | Q30: 0.05 | R30: 0.05 | S30: 0.7 | T30: 0.1 | U30: 0 | V30: 0.1 | W30: =SUM(Q30:V30) -> 1 | X30: =IF(E30<>"Combat","—",IFERROR(INDEX(Affinity!$A$2:$A$7,MATCH(MAX(INDEX(Affinity!$B$2:$AD$7,0,MATCH(A30,Affinity!$B$1:$AD$1,0))),INDEX(Affinity!$B$2:$AD$7,0,MATCH(A30,Affinity!$B$1:$AD$1,0)),0)),"—")) -> Emotional | Y30: 5 | Z30: 45000 | AA30: 1 | AB30: 70 | AC30: 0 | AD30: -5 | AE30: 0 | AF30: -3 | AG30: 10 | AH30: 0 | AI30: Shared_pool | AJ30: per_turn | AL30: stream | AM30: 3 | AN30: town_hall | AO30: No | AR30: Yes | AX30: OUT_HARBOR_1; OUT_HARBOR_2 | AY30: 2 | AZ30: 2
A31: ST30 | B31: Media Ambush on Seafood Labeling | C31: 水産物表示を巡るぶら下がり取材 | D31: Suisanbutsu Hyōji o Meguru Burasagari Shuzai | E31: Combat | F31: Press tone | G31: Percentage | H31: 50 | I31: 30 | J31: =IF(AND(ISNUMBER(H31),ISNUMBER(I31)),IF(H31=0,"",I31/H31),"varies") -> 0.6 | K31: 11 | L31: 3 | M31: 3 | N31: 2 | O31: 5 | P31: 15 | Q31: 1 | R31: 0 | S31: 0 | T31: 0 | U31: 0 | V31: 0 | W31: =SUM(Q31:V31) -> 1 | X31: =IF(E31<>"Combat","—",IFERROR(INDEX(Affinity!$A$2:$A$7,MATCH(MAX(INDEX(Affinity!$B$2:$AD$7,0,MATCH(A31,Affinity!$B$1:$AD$1,0))),INDEX(Affinity!$B$2:$AD$7,0,MATCH(A31,Affinity!$B$1:$AD$1,0)),0)),"—")) -> Appeal | Y31: 2 | Z31: 15000 | AA31: 3 | AB31: 70 | AC31: 1 | AD31: -1 | AE31: 0 | AF31: -1 | AG31: 5 | AH31: -5 | AI31: Shared_pool | AJ31: pool | AK31: 15 | AL31: continuous | AM31: 2 | AN31: media_ambush | AO31: No | AP31: No | AQ31: No | AR31: No | AX31: ST19 | AY31: 1 | BA31: 1
A32: ST31 | B32: Hearing on Fishery Quotas | C32: 漁獲枠に関する公聴会 | D32: Gyokaku-waku ni Kansuru Kōchōkai | E32: Combat | F32: Favorability | G32: Percentage | H32: 100 | I32: 72 | J32: =IF(AND(ISNUMBER(H32),ISNUMBER(I32)),IF(H32=0,"",I32/H32),"varies") -> 0.72 | K32: 10 | L32: 4 | M32: 5 | N32: 6 | O32: 30 | P32: 30 | Q32: 0 | R32: 0.2 | S32: 0.5 | T32: 0 | U32: 0.1 | V32: 0.2 | W32: =SUM(Q32:V32) -> 1 | X32: =IF(E32<>"Combat","—",IFERROR(INDEX(Affinity!$A$2:$A$7,MATCH(MAX(INDEX(Affinity!$B$2:$AD$7,0,MATCH(A32,Affinity!$B$1:$AD$1,0))),INDEX(Affinity!$B$2:$AD$7,0,MATCH(A32,Affinity!$B$1:$AD$1,0)),0)),"—")) -> Earnest | Y32: 1 | Z32: 10000 | AA32: 1 | AB32: 40 | AC32: 0 | AD32: -1 | AE32: 1000 | AF32: 0 | AG32: 1 | AH32: 0 | AI32: Shared_pool | AJ32: per_turn | AL32: reset | AM32: 2 | AO32: No | AR32: Yes | AX32: ST13 | AY32: 4 | BA32: 1
A33: ST32 | B33: Press Conference on Wilderness Protection | C33: 原生自然の保護記者会見 | D33: Gensei Shizen no Hogo Kisha Kaiken | E33: Combat | F33: Press tone | G33: Numerical | H33: 100 | I33: 55 | J33: =IF(AND(ISNUMBER(H33),ISNUMBER(I33)),IF(H33=0,"",I33/H33),"varies") -> 0.55 | K33: 6 | L33: 3 | M33: 5 | N33: 4 | O33: 20 | P33: 45 | Q33: 0.9 | R33: 0 | S33: 0 | T33: 0 | U33: 0.05 | V33: 0.05 | W33: =SUM(Q33:V33) -> 1 | X33: =IF(E33<>"Combat","—",IFERROR(INDEX(Affinity!$A$2:$A$7,MATCH(MAX(INDEX(Affinity!$B$2:$CU$7,0,MATCH(A33,Affinity!$B$1:$CU$1,0))),INDEX(Affinity!$B$2:$CU$7,0,MATCH(A33,Affinity!$B$1:$CU$1,0)),0)),"—")) -> Earnest | Y33: 1 | Z33: 30000 | AA33: 1 | AB33: 60 | AC33: 1 | AD33: 0 | AE33: 0 | AF33: -2 | AG33: 5 | AH33: -2 | AI33: Single | AJ33: per_turn | AL33: single | AM33: 1 | AN33: press_conference | AO33: Yes | AQ33: No | AR33: Yes | AX33: ST04 | AY33: 2 | BA33: 2
A34: ST33 | B34: Hearing on Wilderness Protection | C34: 原生自然の保護に関する公聴会 | D34: Gensei Shizen no Hogo ni Kansuru Kōchōkai | E34: Combat | F34: Favorability | G34: Percentage | H34: 100 | I34: 66 | J34: =IF(AND(ISNUMBER(H34),ISNUMBER(I34)),IF(H34=0,"",I34/H34),"varies") -> 0.66 | K34: 10 | L34: 5 | M34: 5 | N34: 7 | O34: 30 | P34: 30 | Q34: 0 | R34: 0.1 | S34: 0.65 | T34: 0 | U34: 0.2 | V34: 0.05 | W34: =SUM(Q34:V34) -> 1 | X34: =IF(E34<>"Combat","—",IFERROR(INDEX(Affinity!$A$2:$A$7,MATCH(MAX(INDEX(Affinity!$B$2:$CU$7,0,MATCH(A34,Affinity!$B$1:$CU$1,0))),INDEX(Affinity!$B$2:$CU$7,0,MATCH(A34,Affinity!$B$1:$CU$1,0)),0)),"—")) -> Earnest | Y34: 2 | Z34: 10000 | AA34: 1 | AB34: 40 | AC34: 0 | AD34: -1 | AE34: 1000 | AF34: 0 | AG34: 1 | AH34: 0 | AI34: Shared_pool | AJ34: per_turn | AL34: reset | AM34: 2 | AO34: No | AR34: Yes | AX34: ST10 | AY34: 4 | BA34: 1
A35: ST34 | B35: Town Hall on Wilderness Protection | C35: 原生自然の保護を巡る住民集会 | D35: Gensei Shizen no Hogo o Meguru Jūmin Shūkai | E35: Combat | F35: Appeasement | G35: Percentage | H35: 100 | I35: 53 | J35: =IF(AND(ISNUMBER(H35),ISNUMBER(I35)),IF(H35=0,"",I35/H35),"varies") -> 0.53 | K35: 17 | L35: 3 | M35: 5 | N35: 6 | O35: 15 | P35: 20 | Q35: 0.1 | R35: 0.1 | S35: 0.7 | T35: 0.1 | U35: 0 | V35: 0 | W35: =SUM(Q35:V35) -> 1 | X35: =IF(E35<>"Combat","—",IFERROR(INDEX(Affinity!$A$2:$A$7,MATCH(MAX(INDEX(Affinity!$B$2:$CU$7,0,MATCH(A35,Affinity!$B$1:$CU$1,0))),INDEX(Affinity!$B$2:$CU$7,0,MATCH(A35,Affinity!$B$1:$CU$1,0)),0)),"—")) -> Emotional | Y35: 5 | Z35: 45000 | AA35: 1 | AB35: 70 | AC35: 0 | AD35: -5 | AE35: 0 | AF35: -3 | AG35: 10 | AH35: 0 | AI35: Shared_pool | AJ35: per_turn | AL35: stream | AM35: 3 | AN35: town_hall | AO35: No | AR35: Yes | AX35: ST05 | AY35: 2 | AZ35: 2
A36: ST35 | B36: Party Caucus on Wilderness Protection | C36: 原生自然の保護党内会合 | D36: Gensei Shizen no Hogo Tōnai Kaigō | E36: Combat | F36: Support | G36: Percentage | H36: 100 | I36: 49 | J36: =IF(AND(ISNUMBER(H36),ISNUMBER(I36)),IF(H36=0,"",I36/H36),"varies") -> 0.49 | K36: 10 | L36: 3 | M36: 5 | N36: 5 | O36: 20 | P36: 40 | Q36: 0 | R36: 0.55 | S36: 0 | T36: 0 | U36: 0 | V36: 0.45 | W36: =SUM(Q36:V36) -> 1 | X36: =IF(E36<>"Combat","—",IFERROR(INDEX(Affinity!$A$2:$A$7,MATCH(MAX(INDEX(Affinity!$B$2:$CU$7,0,MATCH(A36,Affinity!$B$1:$CU$1,0))),INDEX(Affinity!$B$2:$CU$7,0,MATCH(A36,Affinity!$B$1:$CU$1,0)),0)),"—")) -> Earnest | Y36: 0 | Z36: 20000 | AA36: 1 | AB36: 90 | AC36: 2 | AD36: 0 | AE36: 0 | AF36: -1 | AG36: 1 | AH36: -2 | AI36: Shared_pool | AJ36: per_turn | AL36: continuous | AM36: 2 | AO36: No | AR36: Yes | AT36: Yes | AX36: ST03 | AY36: 4
A37: ST36 | B37: Town Hall on Rural Hospitals | C37: 地方病院網を巡る住民集会 | D37: Chihō Byōin-mō o Meguru Jūmin Shūkai | E37: Combat | F37: Appeasement | G37: Percentage | H37: 100 | I37: 53 | J37: =IF(AND(ISNUMBER(H37),ISNUMBER(I37)),IF(H37=0,"",I37/H37),"varies") -> 0.53 | K37: 17 | L37: 3 | M37: 5 | N37: 6 | O37: 15 | P37: 20 | Q37: 0.1 | R37: 0.1 | S37: 0.7 | T37: 0.1 | U37: 0 | V37: 0 | W37: =SUM(Q37:V37) -> 1 | X37: =IF(E37<>"Combat","—",IFERROR(INDEX(Affinity!$A$2:$A$7,MATCH(MAX(INDEX(Affinity!$B$2:$CU$7,0,MATCH(A37,Affinity!$B$1:$CU$1,0))),INDEX(Affinity!$B$2:$CU$7,0,MATCH(A37,Affinity!$B$1:$CU$1,0)),0)),"—")) -> Emotional | Y37: 5 | Z37: 45000 | AA37: 1 | AB37: 70 | AC37: 0 | AD37: -5 | AE37: 0 | AF37: -3 | AG37: 10 | AH37: 0 | AI37: Shared_pool | AJ37: per_turn | AL37: stream | AM37: 3 | AN37: town_hall | AO37: No | AR37: Yes | AX37: ST05 | AY37: 2 | AZ37: 2
A38: ST37 | B38: Hearing on Rural Hospitals | C38: 地方病院網に関する公聴会 | D38: Chihō Byōin-mō ni Kansuru Kōchōkai | E38: Combat | F38: Favorability | G38: Percentage | H38: 100 | I38: 81 | J38: =IF(AND(ISNUMBER(H38),ISNUMBER(I38)),IF(H38=0,"",I38/H38),"varies") -> 0.81 | K38: 10 | L38: 5 | M38: 5 | N38: 5 | O38: 30 | P38: 40 | Q38: 0.15 | R38: 0 | S38: 0.1 | T38: 0.1 | U38: 0.65 | V38: 0 | W38: =SUM(Q38:V38) -> 1 | X38: =IF(E38<>"Combat","—",IFERROR(INDEX(Affinity!$A$2:$A$7,MATCH(MAX(INDEX(Affinity!$B$2:$CU$7,0,MATCH(A38,Affinity!$B$1:$CU$1,0))),INDEX(Affinity!$B$2:$CU$7,0,MATCH(A38,Affinity!$B$1:$CU$1,0)),0)),"—")) -> Emotional | Y38: 1 | Z38: 50000 | AA38: 5 | AB38: 40 | AC38: 5 | AD38: 0 | AE38: 0 | AF38: 0 | AG38: 2 | AH38: 0 | AI38: Shared_pool | AJ38: per_turn | AL38: reset | AM38: 4 | AO38: No | AR38: Yes | AX38: ST17 | AY38: 4 | BA38: 1
A39: ST38 | B39: Policy Study on Rural Hospitals | C39: 地方病院網政策検討会 | D39: Chihō Byōin-mō Seisaku Kentōkai | E39: Combat | F39: Consensus | G39: Percentage | H39: 50 | I39: 44 | J39: =IF(AND(ISNUMBER(H39),ISNUMBER(I39)),IF(H39=0,"",I39/H39),"varies") -> 0.88 | K39: 10 | L39: 5 | M39: 5 | N39: 10 | O39: 1 | P39: 10 | Q39: 0 | R39: 0 | S39: 0 | T39: 0 | U39: 0.8 | V39: 0.2 | W39: =SUM(Q39:V39) -> 1 | X39: =IF(E39<>"Combat","—",IFERROR(INDEX(Affinity!$A$2:$A$7,MATCH(MAX(INDEX(Affinity!$B$2:$CU$7,0,MATCH(A39,Affinity!$B$1:$CU$1,0))),INDEX(Affinity!$B$2:$CU$7,0,MATCH(A39,Affinity!$B$1:$CU$1,0)),0)),"—")) -> Earnest | Y39: 1 | Z39: 15000 | AA39: 1 | AB39: 55 | AC39: 1 | AD39: 0 | AE39: 0 | AF39: 0 | AG39: 5 | AH39: 0 | AI39: Shared_pool | AJ39: per_turn | AL39: stream | AM39: 2 | AN39: policy_study | AO39: No | AQ39: No | AR39: Yes | AX39: ST21 | AY39: 2
A40: ST39 | B40: Party Caucus on Rural Hospitals | C40: 地方病院網党内会合 | D40: Chihō Byōin-mō Tōnai Kaigō | E40: Combat | F40: Support | G40: Percentage | H40: 100 | I40: 49 | J40: =IF(AND(ISNUMBER(H40),ISNUMBER(I40)),IF(H40=0,"",I40/H40),"varies") -> 0.49 | K40: 10 | L40: 3 | M40: 5 | N40: 5 | O40: 20 | P40: 40 | Q40: 0 | R40: 0.55 | S40: 0 | T40: 0 | U40: 0 | V40: 0.45 | W40: =SUM(Q40:V40) -> 1 | X40: =IF(E40<>"Combat","—",IFERROR(INDEX(Affinity!$A$2:$A$7,MATCH(MAX(INDEX(Affinity!$B$2:$CU$7,0,MATCH(A40,Affinity!$B$1:$CU$1,0))),INDEX(Affinity!$B$2:$CU$7,0,MATCH(A40,Affinity!$B$1:$CU$1,0)),0)),"—")) -> Emotional | Y40: 0 | Z40: 20000 | AA40: 1 | AB40: 90 | AC40: 2 | AD40: 0 | AE40: 0 | AF40: -1 | AG40: 1 | AH40: -2 | AI40: Shared_pool | AJ40: per_turn | AL40: continuous | AM40: 2 | AO40: No | AR40: Yes | AT40: Yes | AX40: ST03 | AY40: 4
...

Sheet Levels
A1: Level ID | B1: Level Description | C1: Cooldown Period (game clock units before this level is available to play again) | D1: Level Tier | E1: Cost in XP to Unlock if Policy Research Assistant is Vacant | F1: Cost in XP to Unlock if Policy Research Assistant is Tier 0 | G1: Cost in XP to Unlock if Policy Research Assistant is Tier 1 | H1: Cost in XP to Unlock if Policy Research Assistant is Tier 2 | I1: Stage ID for Part 1 | J1: Stage ID for Part 2 | K1: Stage ID for Part 3 | L1: Stage ID for Part 4 | M1: Stage ID for Part 5 | N1: Stage ID for Part 6 | O1: Stage ID for Part 7 | P1: Stage ID for Part 8 | Q1: Stage ID for Part 9 | R1: Stage ID for Part 10 | S1: Bonus Win Range ΔJiban | T1: Bonus Win Range ΔYen | U1: Bonus Win Range ΔReputation | V1: Bonus Win Range ΔXP | W1: Bonus Win Range ΔParty support | X1: Win ΔBO01 | Y1: Win ΔBO02 | Z1: Win ΔBO03 | AA1: Win ΔBO04 | AB1: Win ΔBO05 | AC1: Win ΔBO06 | AD1: Win ΔBO07 | AE1: Win ΔBO08 | AF1: Win ΔBO09 | AG1: Win ΔBO10 | AH1: Win ΔBO11 | AI1: Win ΔBO12 | AJ1: Win ΔBO13 | AK1: Win ΔBO14 | AL1: Win ΔBO15 | AM1: Win ΔBO16 | AN1: One-Time (Yes/No) | AO1: Special Trigger | AP1: Win ΔBO17 | AQ1: Win ΔBO18 | AR1: Win ΔBO19 | AS1: Win ΔBO20 | AT1: Win ΔBO21 | AU1: Win ΔBO22 | AV1: Win ΔBO23 | AW1: Win ΔBO24 | AX1: Win ΔBO25 | AY1: Win ΔBO26 | AZ1: Win ΔBO27 | BA1: Win ΔBO28 | BB1: Win ΔBO29 | BC1: Win ΔBO30 | BD1: Win ΔBO31 | BE1: Win ΔBO32 | BF1: Weekend OK (Yes/No) | BG1: Needs Discovery (Yes/No) | BH1: Host Org (BOxx)
A2: LV01 | B2: Talking with Constituents | C2: 36 | D2: 0 | E2: 0 | F2: 0 | G2: 0 | H2: 0 | I2: ST05 | J2: ST07 | K2: N/A | L2: N/A | M2: N/A | N2: N/A | O2: N/A | P2: N/A | Q2: N/A | R2: N/A | S2: 0 | T2: 0 | U2: 0 | V2: 0 | W2: 0% | X2: 0 | Y2: 0 | Z2: 0-1 | AA2: 0-1 | AB2: 0 | AC2: 0-1 | AD2: 0 | AE2: 0 | AF2: 0 | AG2: 0 | AH2: 0 | AI2: 0 | AJ2: 0 | AK2: 0 | AL2: 0 | AM2: 0 | AN2: No
A3: LV02 | B3: Meeting Lobbyists | C3: 18 | D3: 0 | E3: 0 | F3: 0 | G3: 0 | H3: 0 | I3: ST20 | J3: ST19 | K3: N/A | L3: N/A | M3: N/A | N3: N/A | O3: N/A | P3: N/A | Q3: N/A | R3: N/A | S3: 0 | T3: 0 | U3: 0 | V3: 0 | W3: 0% | X3: 0 | Y3: 0 | Z3: 0 | AA3: 0 | AB3: 0 | AC3: 0 | AD3: 0 | AE3: 0 | AF3: 0 | AG3: 0 | AH3: 0 | AI3: 0 | AJ3: 0 | AK3: 0 | AL3: 0 | AM3: 0 | AN3: No
A4: LV03 | B4: Policy Listening and Study | C4: 54 | D4: 0 | E4: 0 | F4: 0 | G4: 0 | H4: 0 | I4: ST05 | J4: ST20 | K4: ST21 | L4: N/A | M4: N/A | N4: N/A | O4: N/A | P4: N/A | Q4: N/A | R4: N/A | S4: 0 | T4: 0 | U4: 0 | V4: 0 | W4: 0% | X4: 0 | Y4: 0-1 | Z4: 0 | AA4: 0 | AB4: 0-2 | AC4: 0 | AD4: 0 | AE4: 0 | AF4: 0-1 | AG4: 0 | AH4: 0 | AI4: 0 | AJ4: 0 | AK4: 0 | AL4: 0 | AM4: 0 | AN4: No
A5: LV04 | B5: Hearing at the Committee on the Environment | C5: 54 | D5: 0 | E5: 0 | F5: 0 | G5: 0 | H5: 0 | I5: ST03 | J5: ST04 | K5: ST10 | L5: N/A | M5: N/A | N5: N/A | O5: N/A | P5: N/A | Q5: N/A | R5: N/A | S5: 0-3 | T5: 0-1100 | U5: 0-5 | V5: 0 | W5: 0% | X5: 0 | Y5: 0 | Z5: 0-1 | AA5: 0-1 | AB5: 0 | AC5: 0-1 | AD5: 0 | AE5: 0 | AF5: 0 | AG5: 1-3 | AH5: 0 | AI5: 0 | AJ5: 0 | AK5: 0 | AL5: 0 | AM5: 0 | AN5: No
A6: LV05 | B6: Media Rounds | C6: 90 | D6: 0 | E6: 0 | F6: 0 | G6: 0 | H6: 0 | I6: ST04 | J6: ST06 | K6: ST03 | L6: ST05 | M6: ST19 | N6: N/A | O6: N/A | P6: N/A | Q6: N/A | R6: N/A | S6: 0 | T6: 0-5000 | U6: 2 | V6: 25 | W6: 0-3% | X6: 0 | Y6: 0-2 | Z6: 0-5 | AA6: 0-1 | AB6: 0-1 | AC6: 0-2 | AD6: 0-1 | AE6: 2-7 | AF6: 0-1 | AG6: 0-2 | AH6: 0 | AI6: 0 | AJ6: 0 | AK6: 0 | AL6: 0 | AM6: 0 | AN6: No
A7: LV06 | B7: Providing the Party Agricultural Policy Support | C7: 126 | D7: 0 | E7: 0 | F7: 0 | G7: 0 | H7: 0 | I7: ST03 | J7: ST04 | K7: ST20 | L7: ST21 | M7: ST03 | N7: ST13 | O7: ST02 | P7: N/A | Q7: N/A | R7: N/A | S7: 0-3 | T7: 0-22000 | U7: 0 | V7: 5 | W7: 2-10% | X7: 0-3 | Y7: 0-3 | Z7: 0-1 | AA7: 0-1 | AB7: 0 | AC7: 0-1 | AD7: 0-2 | AE7: 0-1 | AF7: 0-2 | AG7: 0-2 | AH7: 0 | AI7: 0 | AJ7: 0 | AK7: 0 | AL7: 0 | AM7: 0 | AN7: No
A8: LV07 | B8: Providing the Party Infrastructure Policy Support | C8: 180 | D8: 0 | E8: 25 | F8: 20 | G8: 10 | H8: 0 | I8: ST20 | J8: ST21 | K8: ST03 | L8: ST06 | M8: ST15 | N8: ST02 | O8: ST19 | P8: N/A | Q8: N/A | R8: N/A | S8: 0-2 | T8: 0-25000 | U8: 0 | V8: 5 | W8: 3-12% | X8: 0-3 | Y8: 0-3 | Z8: 0 | AA8: 0-2 | AB8: 0-3 | AC8: 0 | AD8: 0-2 | AE8: 0 | AF8: 0-6 | AG8: 0 | AH8: 0 | AI8: 0 | AJ8: 0 | AK8: 0 | AL8: 0 | AM8: 0 | AN8: No
A9: LV08 | B9: Fighting on the Floor for the Party | C9: 270 | D9: 0 | E9: 50 | F9: 25 | G9: 15 | H9: 10 | I9: ST04 | J9: ST02 | K9: ST04 | L9: ST02 | M9: ST19 | N9: ST02 | O9: N/A | P9: N/A | Q9: N/A | R9: N/A | S9: 0 | T9: 3000-19000 | U9: 7 | V9: 15 | W9: 10-17% | X9: 2-5 | Y9: 2-5 | Z9: 0 | AA9: 0 | AB9: 0 | AC9: 0 | AD9: 0-2 | AE9: 0-4 | AF9: 0 | AG9: 0 | AH9: 0 | AI9: 0 | AJ9: 0 | AK9: 0 | AL9: 0 | AM9: 0 | AN9: No
A10: LV09 | B10: Filling in at Committees | C10: 270 | D10: 0 | E10: 50 | F10: 25 | G10: 15 | H10: 10 | I10: ST01 | J10: ST10 | K10: ST21 | L10: ST17 | M10: ST01 | N10: ST14 | O10: N/A | P10: N/A | Q10: N/A | R10: N/A | S10: 0 | T10: 0-22000 | U10: 3 | V10: 10 | W10: 10-22% | X10: 0-2 | Y10: 1-5 | Z10: 0 | AA10: 0 | AB10: 0 | AC10: 0 | AD10: 0 | AE10: 0 | AF10: 0 | AG10: 0 | AH10: 0 | AI10: 0 | AJ10: 0 | AK10: 0 | AL10: 0 | AM10: 0 | AN10: No
A11: LV10 | B11: Advancing a Bill to Protect Hometown Markets | C11: 360 | D11: 1 | E11: 150 | F11: 100 | G11: 50 | H11: 10 | I11: ST05 | J11: ST04 | K11: ST05 | L11: ST21 | M11: ST20 | N11: ST21 | O11: ST01 | P11: ST06 | Q11: ST15 | R11: ST02 | S11: 4-16 | T11: 5000-25000 | U11: 6-12 | V11: 55-95 | W11: 2-6% | X11: 0 | Y11: 0 | Z11: 5-9 | AA11: 2-4 | AB11: 0-4 | AC11: 1-4 | AD11: 3-6 | AE11: 0 | AF11: 0 | AG11: 2-8 | AH11: 0 | AI11: 0 | AJ11: 0 | AK11: 0 | AL11: 0 | AM11: 0 | AN11: No
A12: LV11 | B12: Meeting with Student Organizers | C12: 90 | D12: 1 | E12: 150 | F12: 100 | G12: 50 | H12: 10 | I12: ST07 | J12: ST05 | K12: ST21 | L12: N/A | M12: N/A | N12: N/A | O12: N/A | P12: N/A | Q12: N/A | R12: N/A | S12: 0-1 | T12: 3000-12000 | U12: 1-2 | V12: 15-30 | W12: 1-4% | X12: 0 | Y12: 0 | Z12: 0-1 | AA12: 0 | AB12: 0 | AC12: 0 | AD12: 0 | AE12: 0 | AF12: 0 | AG12: 0 | AH12: 2-4 | AI12: 0 | AJ12: 0 | AK12: 0 | AL12: 0 | AM12: 0 | AN12: No
A13: LV12 | B13: Family Outreach Tour | C13: 108 | D13: 1 | E13: 150 | F13: 100 | G13: 50 | H13: 10 | I13: ST07 | J13: ST05 | K13: ST10 | L13: ST15 | M13: N/A | N13: N/A | O13: N/A | P13: N/A | Q13: N/A | R13: N/A | S13: 0-2 | T13: 5000-15000 | U13: 1-3 | V13: 20-35 | W13: 2-5% | X13: 0 | Y13: 0 | Z13: 0-1 | AA13: 0 | AB13: 0 | AC13: 1-2 | AD13: 0 | AE13: 0 | AF13: 0 | AG13: 0 | AH13: 0 | AI13: 2-4 | AJ13: 0 | AK13: 0 | AL13: 0 | AM13: 0 | AN13: No
A14: LV13 | B14: Backing the Local Artisans | C14: 108 | D14: 1 | E14: 150 | F14: 100 | G14: 50 | H14: 10 | I14: ST20 | J14: ST02 | K14: ST16 | L14: ST15 | M14: N/A | N14: N/A | O14: N/A | P14: N/A | Q14: N/A | R14: N/A | S14: 0-2 | T14: 5000-18000 | U14: 1-3 | V14: 20-35 | W14: 2-5% | X14: 0 | Y14: 0 | Z14: 0 | AA14: 0 | AB14: 1-2 | AC14: 0 | AD14: 0 | AE14: 0 | AF14: 0 | AG14: 0 | AH14: 0 | AI14: 0 | AJ14: 2-4 | AK14: 0 | AL14: 0 | AM14: 0 | AN14: No
A15: LV14 | B15: Fixing the Daily Commute | C15: 144 | D15: 1 | E15: 150 | F15: 100 | G15: 50 | H15: 10 | I15: ST07 | J15: ST20 | K15: ST15 | L15: ST17 | M15: ST02 | N15: N/A | O15: N/A | P15: N/A | Q15: N/A | R15: N/A | S15: 0-2 | T15: 6000-20000 | U15: 1-3 | V15: 25-40 | W15: 2-6% | X15: 0 | Y15: 0 | Z15: 0 | AA15: 1-2 | AB15: 0 | AC15: 0 | AD15: 0 | AE15: 0 | AF15: 0 | AG15: 0 | AH15: 0 | AI15: 0 | AJ15: 0 | AK15: 2-4 | AL15: 0 | AM15: 0 | AN15: No
A16: LV15 | B16: Courting the Traditionalist Wing | C16: 180 | D16: 1 | E16: 150 | F16: 100 | G16: 50 | H16: 10 | I16: ST03 | J16: ST06 | K16: ST14 | L16: ST18 | M16: ST04 | N16: ST02 | O16: N/A | P16: N/A | Q16: N/A | R16: N/A | S16: 1-3 | T16: 8000-22000 | U16: 2-4 | V16: 25-45 | W16: 3-7% | X16: 1-2 | Y16: 0 | Z16: 0 | AA16: 0 | AB16: 0 | AC16: 0 | AD16: 0 | AE16: 0-1 | AF16: 0 | AG16: 0 | AH16: 0 | AI16: 0 | AJ16: 0 | AK16: 0 | AL16: 2-4 | AM16: 0 | AN16: No
A17: LV16 | B17: Running with the Reform Caucus | C17: 216 | D17: 1 | E17: 150 | F17: 100 | G17: 50 | H17: 10 | I17: ST04 | J17: ST06 | K17: ST12 | L17: ST16 | M17: ST17 | N17: ST21 | O17: ST19 | P17: ST02 | Q17: N/A | R17: N/A | S17: 1-3 | T17: 10000-25000 | U17: 2-5 | V17: 30-55 | W17: 3-8% | X17: 0 | Y17: 0 | Z17: 0 | AA17: 0 | AB17: 0-1 | AC17: 0 | AD17: 0 | AE17: 1-2 | AF17: 0 | AG17: 0 | AH17: 0 | AI17: 0 | AJ17: 0 | AK17: 0 | AL17: 0 | AM17: 2-4 | AN17: No
A18: LV17 | B18: Building the Next-Generation Coalition | C18: 252 | D18: 1 | E18: 150 | F18: 100 | G18: 50 | H18: 10 | I18: ST07 | J18: ST05 | K18: ST21 | L18: ST05 | M18: ST10 | N18: ST15 | O18: ST04 | P18: ST19 | Q18: ST02 | R18: N/A | S18: 1-4 | T18: 12000-28000 | U18: 2-5 | V18: 35-60 | W18: 4-9% | X18: 0 | Y18: 0 | Z18: 0-1 | AA18: 0 | AB18: 0 | AC18: 0-1 | AD18: 0 | AE18: 0 | AF18: 0 | AG18: 0 | AH18: 1-3 | AI18: 1-3 | AJ18: 0 | AK18: 0 | AL18: 0 | AM18: 0 | AN18: No
A19: LV18 | B19: Uniting Main Street and Transit Riders | C19: 270 | D19: 1 | E19: 150 | F19: 100 | G19: 50 | H19: 10 | I19: ST20 | J19: ST02 | K19: ST16 | L19: ST15 | M19: ST17 | N19: ST20 | O19: ST02 | P19: ST19 | Q19: ST04 | R19: ST02 | S19: 2-4 | T19: 15000-30000 | U19: 3-6 | V19: 40-65 | W19: 5-10% | X19: 0 | Y19: 0 | Z19: 0 | AA19: 0-1 | AB19: 0-1 | AC19: 0 | AD19: 0 | AE19: 0 | AF19: 0 | AG19: 0 | AH19: 0 | AI19: 0 | AJ19: 1-3 | AK19: 1-3 | AL19: 0 | AM19: 0 | AN19: No
A20: LV19 | B20: Bridging Old Guard and New Wave | C20: 270 | D20: 1 | E20: 150 | F20: 100 | G20: 50 | H20: 10 | I20: ST03 | J20: ST06 | K20: ST18 | L20: ST14 | M20: ST04 | N20: ST12 | O20: ST16 | P20: ST17 | Q20: ST21 | R20: ST02 | S20: 2-4 | T20: 15000-30000 | U20: 3-6 | V20: 40-65 | W20: 5-10% | X20: 0-1 | Y20: 0 | Z20: 0 | AA20: 0 | AB20: 0 | AC20: 0 | AD20: 0 | AE20: 0-1 | AF20: 0 | AG20: 0 | AH20: 0 | AI20: 0 | AJ20: 0 | AK20: 0 | AL20: 1-3 | AM20: 1-3 | AN20: No
A21: LV20 | B21: Rallying Youth and Labor | C21: 180 | D21: 2 | E21: 300 | F21: 250 | G21: 200 | H21: 100 | I21: ST21 | J21: ST08 | K21: ST03 | L21: ST02 | M21: N/A | N21: N/A | O21: N/A | P21: N/A | Q21: N/A | R21: N/A | S21: 2-5 | T21: 15000-35000 | U21: 3-7 | V21: 40-70 | W21: 5-10% | X21: 0 | Y21: 0-2 | Z21: 0 | AA21: 0 | AB21: 0 | AC21: 0 | AD21: 0 | AE21: 0 | AF21: 2-4 | AG21: 0 | AH21: 2-5 | AI21: 0 | AJ21: 0 | AK21: 0 | AL21: 0 | AM21: 0 | AN21: No
A22: LV21 | B22: A Neighborhood Family Compact | C22: 216 | D22: 2 | E22: 300 | F22: 250 | G22: 200 | H22: 100 | I22: ST05 | J22: ST10 | K22: ST15 | L22: ST08 | M22: ST02 | N22: N/A | O22: N/A | P22: N/A | Q22: N/A | R22: N/A | S22: 2-5 | T22: 18000-38000 | U22: 3-7 | V22: 45-75 | W22: 6-11% | X22: 0 | Y22: 0 | Z22: 0-2 | AA22: 0 | AB22: 0 | AC22: 2-4 | AD22: 0 | AE22: 0 | AF22: 0 | AG22: 0 | AH22: 0 | AI22: 2-5 | AJ22: 0 | AK22: 0 | AL22: 0 | AM22: 0 | AN22: No
